Workbook

Sheet BiWeekly Report
B1: Table 1. Removal Summary. Number of Yellowstone bison removed through state and treaty harvests, sent to slaughter, placed in the Bison Conservation Transfer Program or otherwise removed from the population. Table abbreviations are adult (A), yearling (Y), calf (C), and unknown sex (Unk). Harvest numbers are preliminary, in-season totals that may change. | T1: Table 2. Brucellosis Testing Summary.
T3: Date | V3: Male | AB3: Female
V4: Adult | X4: Yearling | Z4: Calf | AB4: Adult | AD4: Yearling | AF4: Calf
C5: Removal Method | F5: NORTH | L5: WEST | V5: + | W5: - | X5: + | Y5: - | Z5: + | AA5: - | AB5: + | AC5: - | AD5: + | AE5: - | AF5: + | AG5: -
F6: Male | H6: Female | J6: Unk | L6: Male | N6: Female | P6: Unk | T6: 45377 | V6: 6 | W6: 1 | X6: 1 | Y6: 1 | Z6: 0 | AA6: 0 | AB6: 7 | AC6: 6 | AD6: 0 | AE6: 1 | AF6: 1 | AG6: 3
F7: A | G7: Y | H7: A | I7: Y | J7: Unk | K7: C | L7: A | M7: Y | N7: A | O7: Y | P7: Unk | Q7: C
A8: Tribal ad State Hunting | B8: Harvest | C8: Harvest (Mont) | F8: 2 | G8: 0 | H8: 0 | I8: 0 | J8: 0 | K8: 0 | L8: 10 | M8: ='Removals Summary'!K4 -> 0 | N8: 3 | O8: ='Removals Summary'!M4 -> 0 | P8: ='Removals Summary'!N4 -> 0 | Q8: 0
C9: Harvest (CSKT) | F9: 0 | G9: 0 | H9: 0 | I9: 0 | J9: 0 | K9: 0 | L9: 1 | M9: ='Removals Summary'!K5 -> 0 | N9: 2 | O9: ='Removals Summary'!M5 -> 0 | P9: ='Removals Summary'!N5 -> 0 | Q9: 1
C10: Harvest (NPT) | F10: 3 | G10: 0 | H10: 1 | I10: 0 | J10: 0 | K10: 1 | L10: ='Removals Summary'!J6 -> 0 | M10: ='Removals Summary'!K6 -> 0 | N10: 0 | O10: ='Removals Summary'!M6 -> 0 | P10: ='Removals Summary'!N6 -> 0 | Q10: 0
C11: Harvest (CTUIR) | F11: 0 | G11: 0 | H11: 0 | I11: 0 | J11: 0 | K11: 0 | L11: ='Removals Summary'!J7 -> 0 | M11: ='Removals Summary'!K7 -> 0 | N11: ='Removals Summary'!L7 -> 0 | O11: ='Removals Summary'!M7 -> 0 | P11: ='Removals Summary'!N7 -> 0 | Q11: ='Removals Summary'!O7 -> 0
C12: Harvest (SB) | F12: 0 | G12: 0 | H12: 0 | I12: 0 | J12: 0 | K12: 0 | L12: 13 | M12: ='Removals Summary'!K8 -> 0 | N12: ='Removals Summary'!L8 -> 0 | O12: ='Removals Summary'!M8 -> 0 | P12: ='Removals Summary'!N8 -> 0 | Q12: ='Removals Summary'!O8 -> 0 | T12: Total | V12: 6 | W12: 1 | X12: 1 | Y12: 1 | Z12: 0 | AA12: 0 | AB12: 7 | AC12: 6 | AD12: 0 | AE12: 1 | AF12: 1 | AG12: 3
C13: Harvest (YN) | F13: 0 | G13: 0 | H13: 0 | I13: 0 | J13: 0 | K13: 0 | L13: ='Removals Summary'!J9 -> 0 | M13: ='Removals Summary'!K9 -> 0 | N13: 0 | O13: ='Removals Summary'!M9 -> 0 | P13: ='Removals Summary'!N9 -> 0 | Q13: 0 | T13: Total | V13: 9 | AB13: 18
C14: Harvest (BT) | F14: 0 | G14: 0 | H14: 0 | I14: 0 | J14: 0 | K14: 0 | L14: 1 | M14: ='Removals Summary'!K10 -> 0 | N14: 1 | O14: ='Removals Summary'!M10 -> 0 | P14: ='Removals Summary'!N10 -> 0 | Q14: ='Removals Summary'!O10 -> 0
C15: Harvest (NARAP) | F15: 8 | G15: 0 | H15: 1 | I15: 0 | J15: 0 | K15: 0 | L15: ='Removals Summary'!J11 -> 0 | M15: ='Removals Summary'!K11 -> 0 | N15: ='Removals Summary'!L11 -> 0 | O15: ='Removals Summary'!M11 -> 0 | P15: ='Removals Summary'!N11 -> 0 | Q15: ='Removals Summary'!O11 -> 0
C16: Harvest (CROW) | F16: 0 | G16: 0 | H16: 0 | I16: 0 | J16: 0 | K16: 0 | L16: ='Removals Summary'!J12 -> 0 | M16: ='Removals Summary'!K12 -> 0 | N16: ='Removals Summary'!L12 -> 0 | O16: ='Removals Summary'!M12 -> 0 | P16: ='Removals Summary'!N12 -> 0 | Q16: ='Removals Summary'!O12 -> 0
C17: NPS1 | F17: 0 | G17: 0 | H17: 0 | I17: 0 | J17: 0 | K17: 0 | L17: ='Removals Summary'!J13 -> 0 | M17: ='Removals Summary'!K13 -> 0 | N17: ='Removals Summary'!L13 -> 0 | O17: ='Removals Summary'!M13 -> 0 | P17: ='Removals Summary'!N13 -> 0 | Q17: ='Removals Summary'!O13 -> 0 | T17: Table 3. Bison in Gardiner Basin. Numbers of bison counted in the Gardiner basin by ground observers during winter 2023-2024. Bison held within the Stephens Creek Capture Facility are not included in counts.
C18: MTFWP2 | F18: 0 | G18: 0 | H18: 0 | I18: 0 | J18: 0 | K18: 0 | L18: 0 | M18: ='Removals Summary'!K14 -> 0 | N18: ='Removals Summary'!L14 -> 0 | O18: ='Removals Summary'!M14 -> 0 | P18: ='Removals Summary'!N14 -> 0 | Q18: ='Removals Summary'!O14 -> 0
C19: Other | F19: 0 | G19: 0 | H19: 0 | I19: 0 | J19: 0 | K19: 0 | L19: ='Removals Summary'!J15 -> 0 | M19: ='Removals Summary'!K15 -> 0 | N19: ='Removals Summary'!L15 -> 0 | O19: ='Removals Summary'!M15 -> 0 | P19: 0 | Q19: ='Removals Summary'!O15 -> 0
A20: NPS Capture Operation | B20: Other Removal | C20: Tribal Food Transfer Program | F20: ='Removals Summary'!D16 -> 5 | G20: ='Removals Summary'!E16 -> 1 | H20: ='Removals Summary'!F16 -> 7 | I20: ='Removals Summary'!G16 -> 0 | J20: ='Removals Summary'!H16 -> 0 | K20: ='Removals Summary'!I16 -> 1 | L20: ='Removals Summary'!J16 -> 0 | M20: ='Removals Summary'!K16 -> 0 | ... Q20: ='Removals Summary'!O16 -> 0
C21: Capture Pen Mortality | F21: ='Removals Summary'!D18 -> 1 | G21: ='Removals Summary'!E18 -> 0 | H21: ='Removals Summary'!F18 -> 0 | I21: ='Removals Summary'!G18 -> 0 | J21: ='Removals Summary'!H18 -> 0 | K21: ='Removals Summary'!I18 -> 0 | L21: ='Removals Summary'!J18 -> 0 | M21: ='Removals Summary'!K18 -> 0 | ... Q21: ='Removals Summary'!O18 -> 0 | T21: Date | V21: Mammoth to Gardiner | X21: North Entrance to Stephens Creek | Z21: Stephens Creek to Park Boundary | AB21: North of Park Boundary | AD21: Eagle Creek SMA | AF21: Total
C22: MTDOL Management Shooting | F22: ='Removals Summary'!D19 -> 0 | G22: ='Removals Summary'!E19 -> 0 | H22: ='Removals Summary'!F19 -> 0 | I22: ='Removals Summary'!G19 -> 0 | J22: ='Removals Summary'!H19 -> 0 | K22: ='Removals Summary'!I19 -> 0 | L22: ='Removals Summary'!J19 -> 0 | M22: ='Removals Summary'!K19 -> 0 | ... Q22: ='Removals Summary'!O19 -> 0
B23: BCTP | C23: Entered in BCTP | F23: ='Removals Summary'!D17 -> 0 | G23: ='Removals Summary'!E17 -> 1 | H23: ='Removals Summary'!F17 -> 0 | I23: ='Removals Summary'!G17 -> 1 | J23: ='Removals Summary'!H17 -> 0 | K23: ='Removals Summary'!I17 -> 3 | L23: 0 | M23: 0 | N23: 0 | O23: 0 | P23: 0 | Q23: 0
B24: Holding | C24: Holding for BCTP selection | F24: ='Removals Summary'!D20 -> 0 | G24: ='Removals Summary'!E20 -> 0 | H24: ='Removals Summary'!F20 -> 0 | I24: ='Removals Summary'!G20 -> 0 | J24: ='Removals Summary'!H20 -> 0 | K24: ='Removals Summary'!I20 -> 0 | L24: ='Removals Summary'!J20 -> 0 | M24: ='Removals Summary'!K20 -> 0 | ... Q24: ='Removals Summary'!O20 -> 0
C25: Holding for release | F25: =SUM('Removals Summary'!D22,'Removals Summary'!D23) -> 0 | G25: =SUM('Removals Summary'!E22,'Removals Summary'!E23) -> 0 | H25: =SUM('Removals Summary'!F22,'Removals Summary'!F23) -> 0 | I25: =SUM('Removals Summary'!G22,'Removals Summary'!G23) -> 0 | J25: =SUM('Removals Summary'!H22,'Removals Summary'!H23) -> 0 | K25: =SUM('Removals Summary'!I22,'Removals Summary'!I23) -> 0 | L25: ='Removals Summary'!J21 -> 0 | M25: ='Removals Summary'!K21 -> 0 | N25: ='Removals Summary'!L21 -> 0 | O25: ='Removals Summary'!M21 -> 0 | P25: ='Removals Summary'!N21 -> 0 | Q25: ='Removals Summary'!O21 -> 0
C26: Released into park | F26: ='Removals Summary'!D21 -> 1 | G26: ='Removals Summary'!E21 -> 0 | H26: ='Removals Summary'!F21 -> 8 | I26: ='Removals Summary'!G21 -> 0 | J26: ='Removals Summary'!H21 -> 0 | K26: ='Removals Summary'!I21 -> 0 | L26: ='Removals Summary'!J23 -> 0 | M26: ='Removals Summary'!K23 -> 0 | N26: ='Removals Summary'!L23 -> 0 | O26: ='Removals Summary'!M23 -> 0 | P26: ='Removals Summary'!N23 -> 0 | Q26: ='Removals Summary'!O23 -> 0
B27: Removed to Date | C27: Harvest | F27: =SUM(F8:F19) -> 13 | G27: =SUM(G8:G19) -> 0 | H27: =SUM(H8:H19) -> 2 | I27: =SUM(I8:I19) -> 0 | J27: =SUM(J8:J19) -> 0 | K27: =SUM(K8:K19) -> 1 | L27: =SUM(L8:L19) -> 25 | M27: =SUM(M8:M19) -> 0 | ... Q27: =SUM(Q8:Q19) -> 1
C28: Other Removal | F28: =SUM(F20:F22) -> 6 | G28: =SUM(G20:G22) -> 1 | H28: =SUM(H20:H22) -> 7 | I28: =SUM(I20:I22) -> 0 | J28: =SUM(J20:J22) -> 0 | K28: =SUM(K20:K22) -> 1 | L28: =SUM(L20:L22) -> 0 | M28: =SUM(M20:M22) -> 0 | ... Q28: =SUM(Q20:Q22) -> 0 | T28: =IF('Gardiner Basin Counts'!A3<>"",'Gardiner Basin Counts'!A3,"") -> 45299 | V28: =IF('Gardiner Basin Counts'!B3<>"",'Gardiner Basin Counts'!B3,"") -> 0 | X28: =IF('Gardiner Basin Counts'!C3<>"",'Gardiner Basin Counts'!C3,"") -> 0 | Z28: =IF('Gardiner Basin Counts'!D3<>"",'Gardiner Basin Counts'!D3,"") -> 0 | AB28: =IF('Gardiner Basin Counts'!E3<>"",'Gardiner Basin Counts'!E3,"") -> 0 | AD28: =IF('Gardiner Basin Counts'!F3<>"",'Gardiner Basin Counts'!F3,"") -> 0 | AF28: =IF('Gardiner Basin Counts'!G3<>"",'Gardiner Basin Counts'!G3,"") -> 0
C29: BCTP | F29: =F23 -> 0 | G29: =G23 -> 1 | H29: =H23 -> 0 | I29: =I23 -> 1 | J29: =J23 -> 0 | K29: =K23 -> 3 | L29: =L23 -> 0 | M29: =M23 -> 0 | ... Q29: =Q23 -> 0 | T29: =IF('Gardiner Basin Counts'!A4<>"",'Gardiner Basin Counts'!A4,"") -> 45307 | V29: =IF('Gardiner Basin Counts'!B4<>"",'Gardiner Basin Counts'!B4,"") -> 0 | X29: =IF('Gardiner Basin Counts'!C4<>"",'Gardiner Basin Counts'!C4,"") -> 0 | Z29: =IF('Gardiner Basin Counts'!D4<>"",'Gardiner Basin Counts'!D4,"") -> 0 | AB29: =IF('Gardiner Basin Counts'!E4<>"",'Gardiner Basin Counts'!E4,"") -> 0 | AD29: =IF('Gardiner Basin Counts'!F4<>"",'Gardiner Basin Counts'!F4,"") -> 0 | AF29: =IF('Gardiner Basin Counts'!G4<>"",'Gardiner Basin Counts'!G4,"") -> 0
C30: Total Removed | F30: =SUM(F27:F29) -> 19 | G30: =SUM(G27:G29) -> 2 | H30: =SUM(H27:H29) -> 9 | I30: =SUM(I27:I29) -> 1 | J30: =SUM(J27:J29) -> 0 | K30: =SUM(K27:K29) -> 5 | L30: =SUM(L27:L29) -> 25 | M30: =SUM(M27:M29) -> 0 | ... Q30: =SUM(Q27:Q29) -> 1 | T30: =IF('Gardiner Basin Counts'!A5<>"",'Gardiner Basin Counts'!A5,"") -> 45313 | V30: =IF('Gardiner Basin Counts'!B5<>"",'Gardiner Basin Counts'!B5,"") -> 0 | X30: =IF('Gardiner Basin Counts'!C5<>"",'Gardiner Basin Counts'!C5,"") -> 0 | Z30: =IF('Gardiner Basin Counts'!D5<>"",'Gardiner Basin Counts'!D5,"") -> 0 | AB30: =IF('Gardiner Basin Counts'!E5<>"",'Gardiner Basin Counts'!E5,"") -> 0 | AD30: =IF('Gardiner Basin Counts'!F5<>"",'Gardiner Basin Counts'!F5,"") -> 0 | AF30: =IF('Gardiner Basin Counts'!G5<>"",'Gardiner Basin Counts'!G5,"") -> 0
F31: =SUM(F30:K30) -> 36 | L31: =SUM(L30:Q30) -> 32 | T31: =IF('Gardiner Basin Counts'!A6<>"",'Gardiner Basin Counts'!A6,"") -> 45320 | V31: =IF('Gardiner Basin Counts'!B6<>"",'Gardiner Basin Counts'!B6,"") -> 0 | X31: =IF('Gardiner Basin Counts'!C6<>"",'Gardiner Basin Counts'!C6,"") -> 0 | Z31: =IF('Gardiner Basin Counts'!D6<>"",'Gardiner Basin Counts'!D6,"") -> 0 | AB31: =IF('Gardiner Basin Counts'!E6<>"",'Gardiner Basin Counts'!E6,"") -> 0 | AD31: =IF('Gardiner Basin Counts'!F6<>"",'Gardiner Basin Counts'!F6,"") -> 0 | AF31: =IF('Gardiner Basin Counts'!G6<>"",'Gardiner Basin Counts'!G6,"") -> 0
F32: =SUM(F31:Q31) -> 68 | T32: =IF('Gardiner Basin Counts'!A7<>"",'Gardiner Basin Counts'!A7,"") -> 45327 | V32: =IF('Gardiner Basin Counts'!B7<>"",'Gardiner Basin Counts'!B7,"") -> 0 | X32: =IF('Gardiner Basin Counts'!C7<>"",'Gardiner Basin Counts'!C7,"") -> 0 | Z32: =IF('Gardiner Basin Counts'!D7<>"",'Gardiner Basin Counts'!D7,"") -> 0 | AB32: =IF('Gardiner Basin Counts'!E7<>"",'Gardiner Basin Counts'!E7,"") -> 0 | AD32: =IF('Gardiner Basin Counts'!F7<>"",'Gardiner Basin Counts'!F7,"") -> 0 | AF32: =IF('Gardiner Basin Counts'!G7<>"",'Gardiner Basin Counts'!G7,"") -> 0
B33: 1 - Wounded animals shot within Yellowstone by YNP personnel or found dead | T33: =IF('Gardiner Basin Counts'!A8<>"",'Gardiner Basin Counts'!A8,"") -> 45336 | V33: =IF('Gardiner Basin Counts'!B8<>"",'Gardiner Basin Counts'!B8,"") -> 0 | X33: =IF('Gardiner Basin Counts'!C8<>"",'Gardiner Basin Counts'!C8,"") -> 0 | Z33: =IF('Gardiner Basin Counts'!D8<>"",'Gardiner Basin Counts'!D8,"") -> 0 | AB33: =IF('Gardiner Basin Counts'!E8<>"",'Gardiner Basin Counts'!E8,"") -> 0 | AD33: =IF('Gardiner Basin Counts'!F8<>"",'Gardiner Basin Counts'!F8,"") -> 0 | AF33: =IF('Gardiner Basin Counts'!G8<>"",'Gardiner Basin Counts'!G8,"") -> 0
B34: 2 - Wounding loss reported by MTFWP | T34: =IF('Gardiner Basin Counts'!A9<>"",'Gardiner Basin Counts'!A9,"") -> 45348 | V34: =IF('Gardiner Basin Counts'!B9<>"",'Gardiner Basin Counts'!B9,"") -> 0 | X34: =IF('Gardiner Basin Counts'!C9<>"",'Gardiner Basin Counts'!C9,"") -> 0 | Z34: =IF('Gardiner Basin Counts'!D9<>"",'Gardiner Basin Counts'!D9,"") -> 0 | AB34: =IF('Gardiner Basin Counts'!E9<>"",'Gardiner Basin Counts'!E9,"") -> 0 | AD34: =IF('Gardiner Basin Counts'!F9<>"",'Gardiner Basin Counts'!F9,"") -> 0 | AF34: =IF('Gardiner Basin Counts'!G9<>"",'Gardiner Basin Counts'!G9,"") -> 0
T35: =IF('Gardiner Basin Counts'!A10<>"",'Gardiner Basin Counts'!A10,"") -> 45357 | V35: =IF('Gardiner Basin Counts'!B10<>"",'Gardiner Basin Counts'!B10,"") -> 12 | X35: =IF('Gardiner Basin Counts'!C10<>"",'Gardiner Basin Counts'!C10,"") -> 0 | Z35: =IF('Gardiner Basin Counts'!D10<>"",'Gardiner Basin Counts'!D10,"") -> 0 | AB35: =IF('Gardiner Basin Counts'!E10<>"",'Gardiner Basin Counts'!E10,"") -> 0 | AD35: =IF('Gardiner Basin Counts'!F10<>"",'Gardiner Basin Counts'!F10,"") -> 0 | AF35: =IF('Gardiner Basin Counts'!G10<>"",'Gardiner Basin Counts'!G10,"") -> 12
T36: =IF('Gardiner Basin Counts'!A11<>"",'Gardiner Basin Counts'!A11,"") -> 45363 | V36: =IF('Gardiner Basin Counts'!B11<>"",'Gardiner Basin Counts'!B11,"") -> 42 | X36: =IF('Gardiner Basin Counts'!C11<>"",'Gardiner Basin Counts'!C11,"") -> 0 | Z36: =IF('Gardiner Basin Counts'!D11<>"",'Gardiner Basin Counts'!D11,"") -> 0 | AB36: =IF('Gardiner Basin Counts'!E11<>"",'Gardiner Basin Counts'!E11,"") -> 0 | AD36: =IF('Gardiner Basin Counts'!F11<>"",'Gardiner Basin Counts'!F11,"") -> 0 | AF36: =IF('Gardiner Basin Counts'!G11<>"",'Gardiner Basin Counts'!G11,"") -> 42
T37: =IF('Gardiner Basin Counts'!A12<>"",'Gardiner Basin Counts'!A12,"") -> 45369 | V37: =IF('Gardiner Basin Counts'!B12<>"",'Gardiner Basin Counts'!B12,"") -> 54 | X37: =IF('Gardiner Basin Counts'!C12<>"",'Gardiner Basin Counts'!C12,"") -> 102 | Z37: =IF('Gardiner Basin Counts'!D12<>"",'Gardiner Basin Counts'!D12,"") -> 0 | AB37: =IF('Gardiner Basin Counts'!E12<>"",'Gardiner Basin Counts'!E12,"") -> 0 | AD37: =IF('Gardiner Basin Counts'!F12<>"",'Gardiner Basin Counts'!F12,"") -> 0 | AF37: =IF('Gardiner Basin Counts'!G12<>"",'Gardiner Basin Counts'!G12,"") -> 156
T38: =IF('Gardiner Basin Counts'!A13<>"",'Gardiner Basin Counts'!A13,"") -> 45376 | V38: =IF('Gardiner Basin Counts'!B13<>"",'Gardiner Basin Counts'!B13,"") -> 9 | X38: =IF('Gardiner Basin Counts'!C13<>"",'Gardiner Basin Counts'!C13,"") -> 58 | Z38: =IF('Gardiner Basin Counts'!D13<>"",'Gardiner Basin Counts'!D13,"") -> 0 | AB38: =IF('Gardiner Basin Counts'!E13<>"",'Gardiner Basin Counts'!E13,"") -> 0 | AD38: =IF('Gardiner Basin Counts'!F13<>"",'Gardiner Basin Counts'!F13,"") -> 0 | AF38: =IF('Gardiner Basin Counts'!G13<>"",'Gardiner Basin Counts'!G13,"") -> 67
T39: =IF('Gardiner Basin Counts'!A15<>"",'Gardiner Basin Counts'!A15,"") -> 45390 | V39: =IF('Gardiner Basin Counts'!B15<>"",'Gardiner Basin Counts'!B15,"") -> 50 | X39: =IF('Gardiner Basin Counts'!C15<>"",'Gardiner Basin Counts'!C15,"") -> 121 | Z39: =IF('Gardiner Basin Counts'!D15<>"",'Gardiner Basin Counts'!D15,"") -> 0 | AB39: =IF('Gardiner Basin Counts'!E15<>"",'Gardiner Basin Counts'!E15,"") -> 0 | AD39: =IF('Gardiner Basin Counts'!F15<>"",'Gardiner Basin Counts'!F15,"") -> 0 | AF39: =IF('Gardiner Basin Counts'!G15<>"",'Gardiner Basin Counts'!G15,"") -> 171
T40: =IF('Gardiner Basin Counts'!A16<>"",'Gardiner Basin Counts'!A16,"") -> 45398 | V40: =IF('Gardiner Basin Counts'!B16<>"",'Gardiner Basin Counts'!B16,"") -> 36 | X40: =IF('Gardiner Basin Counts'!C16<>"",'Gardiner Basin Counts'!C16,"") -> 74 | Z40: =IF('Gardiner Basin Counts'!D16<>"",'Gardiner Basin Counts'!D16,"") -> 85 | AB40: =IF('Gardiner Basin Counts'!E16<>"",'Gardiner Basin Counts'!E16,"") -> 0 | AD40: =IF('Gardiner Basin Counts'!F16<>"",'Gardiner Basin Counts'!F16,"") -> 0 | AF40: =IF('Gardiner Basin Counts'!G16<>"",'Gardiner Basin Counts'!G16,"") -> 195
T41: =IF('Gardiner Basin Counts'!A17<>"",'Gardiner Basin Counts'!A17,"") -> 45406 | V41: =IF('Gardiner Basin Counts'!B17<>"",'Gardiner Basin Counts'!B17,"") -> 45 | X41: =IF('Gardiner Basin Counts'!C17<>"",'Gardiner Basin Counts'!C17,"") -> 110 | Z41: =IF('Gardiner Basin Counts'!D17<>"",'Gardiner Basin Counts'!D17,"") -> 0 | AB41: =IF('Gardiner Basin Counts'!E17<>"",'Gardiner Basin Counts'!E17,"") -> 0 | AD41: =IF('Gardiner Basin Counts'!F17<>"",'Gardiner Basin Counts'!F17,"") -> 0 | AF41: =IF('Gardiner Basin Counts'!G17<>"",'Gardiner Basin Counts'!G17,"") -> 155
...

Sheet Removals Summary
B1: Date | C1: Removal Method | D1: NORTH | J1: WEST
D2: Male | F2: Female | H2: Unk | J2: Male | L2: Female | N2: Unk
D3: A | E3: Y | F3: A | G3: Y | H3: Unk | I3: C | J3: A | K3: Y | L3: A | M3: Y | N3: Unk | O3: C
B4: Operations Year 2022-23 | C4: Harvest (Mont) | D4: 2 | E4: 0 | F4: 0 | G4: 0 | H4: 0 | I4: 0 | J4: 10 | K4: 0 | L4: 3 | M4: 0 | N4: 0 | O4: 0
C5: Harvest (CSKT) | D5: 0 | E5: 0 | F5: 0 | G5: 0 | H5: 0 | I5: 0 | J5: 1 | K5: 0 | L5: 2 | M5: 0 | N5: 0 | O5: 1
C6: Harvest (NPT) | D6: 3 | E6: 0 | F6: 1 | G6: 0 | H6: 0 | I6: 1 | J6: 0 | K6: 0 | L6: 0 | M6: 0 | N6: 0 | O6: 0
C7: Harvest (CTUIR) | D7: 0 | E7: 0 | F7: 0 | G7: 0 | H7: 0 | I7: 0 | J7: 0 | K7: 0 | L7: 0 | M7: 0 | N7: 0 | O7: 0
C8: Harvest (SB) | D8: 0 | E8: 0 | F8: 0 | G8: 0 | H8: 0 | I8: 0 | J8: 9 | K8: 0 | L8: 0 | M8: 0 | N8: 0 | O8: 0
C9: Harvest (YN) | D9: 0 | E9: 0 | F9: 0 | G9: 0 | H9: 0 | I9: 0 | J9: 0 | K9: 0 | L9: 0 | M9: 0 | N9: 0 | O9: 0
C10: Harvest (BT) | D10: 0 | E10: 0 | F10: 0 | G10: 0 | H10: 0 | I10: 0 | J10: 1 | K10: 0 | L10: 1 | M10: 0 | N10: 0 | O10: 0
C11: Harvest (NARAP) | D11: 5 | E11: 0 | F11: 1 | G11: 0 | H11: 0 | I11: 0 | J11: 0 | K11: 0 | L11: 0 | M11: 0 | N11: 0 | O11: 0
C12: Harvest (CROW) | D12: 0 | E12: 0 | F12: 0 | G12: 0 | H12: 0 | I12: 0 | J12: 0 | K12: 0 | L12: 0 | M12: 0 | N12: 0 | O12: 0
C13: NPS1 | D13: 0 | E13: 0 | F13: 0 | G13: 0 | H13: 0 | I13: 0 | J13: 0 | K13: 0 | L13: 0 | M13: 0 | N13: 0 | O13: 0
C14: MTFWP2 | D14: 0 | E14: 0 | F14: 0 | G14: 0 | H14: 0 | I14: 0 | J14: 0 | K14: 0 | L14: 0 | M14: 0 | N14: 0 | O14: 0
C15: Unreported | D15: 0 | E15: 0 | F15: 0 | G15: 0 | H15: 0 | I15: 0 | J15: 0 | K15: 0 | L15: 0 | M15: 0 | N15: 0 | O15: 0
C16: Consigned to Slaughter | D16: 5 | E16: 1 | F16: 7 | G16: 0 | H16: {=SUM(IF('Consignment and Releases'!H:H="Ship to Slaughter",'Consignment and Releases'!F:F,0))} -> 0 | I16: 1 | J16: 0 | K16: 0 | L16: 0 | M16: 0 | N16: 0 | O16: 0 | P16: =SUM(D16:I16) -> 14
C17: Entered in BCTP | D17: 0 | E17: 1 | F17: 0 | G17: 1 | H17: {=SUM(IF('Consignment and Releases'!H:H="BCTP",'Consignment and Releases'!F:F,0))} -> 0 | I17: 3 | J17: 0 | K17: 0 | L17: 0 | M17: 0 | N17: 0 | O17: 0 | P17: =SUM(D17:I17) -> 5
C18: Capture Pen Mortality | D18: 1 | E18: {=SUM(IF('Consignment and Releases'!H:H="Capture Pen Mortality",'Consignment and Releases'!C:C,0))} -> 0 | F18: {=SUM(IF('Consignment and Releases'!H:H="Capture Pen Mortality",'Consignment and Releases'!D:D,0))} -> 0 | G18: {=SUM(IF('Consignment and Releases'!H:H="Capture Pen Mortality",'Consignment and Releases'!E:E,0))} -> 0 | H18: {=SUM(IF('Consignment and Releases'!H:H="Capture Pen Mortality",'Consignment and Releases'!F:F,0))} -> 0 | I18: {=SUM(IF('Consignment and Releases'!H:H="Capture Pen Mortality",'Consignment and Releases'!G:G,0))} -> 0 | J18: 0 | K18: 0 | L18: 0 | M18: 0 | N18: 0 | O18: 0 | P18: =SUM(D18:I18) -> 1
C19: MTDOL Management Shooting | D19: {=SUM(IF('Consignment and Releases'!H:H="Management Shooting",'Consignment and Releases'!B:B,0))} -> 0 | E19: {=SUM(IF('Consignment and Releases'!H:H="Management Shooting",'Consignment and Releases'!C:C,0))} -> 0 | F19: {=SUM(IF('Consignment and Releases'!H:H="Management Shooting",'Consignment and Releases'!D:D,0))} -> 0 | G19: {=SUM(IF('Consignment and Releases'!H:H="Management Shooting",'Consignment and Releases'!E:E,0))} -> 0 | H19: {=SUM(IF('Consignment and Releases'!H:H="Management Shooting",'Consignment and Releases'!F:F,0))} -> 0 | I19: {=SUM(IF('Consignment and Releases'!H:H="Management Shooting",'Consignment and Releases'!G:G,0))} -> 0 | J19: 0 | K19: 0 | L19: 0 | M19: 0 | N19: 0 | O19: 0 | P19: =SUM(D19:I19) -> 0
C20: Holding for BCTP Selection | D20: 0 | E20: 0 | F20: 0 | G20: 0 | H20: 0 | I20: 0 | J20: 0 | K20: 0 | L20: 0 | M20: 0 | N20: 0 | O20: 0 | P20: =SUM(D20:I20) -> 0
C21: Released into Park | D21: 1 | E21: {=SUM(IF('Consignment and Releases'!H:H="Released",'Consignment and Releases'!C:C,0))} -> 0 | F21: 8 | G21: {=SUM(IF('Consignment and Releases'!H:H="Released",'Consignment and Releases'!E:E,0))} -> 0 | H21: {=SUM(IF('Consignment and Releases'!H:H="Released",'Consignment and Releases'!F:F,0))} -> 0 | I21: {=SUM(IF('Consignment and Releases'!H:H="Released",'Consignment and Releases'!G:G,0))} -> 0 | J21: 0 | K21: 0 | L21: 0 | M21: 0 | N21: 0 | O21: 0 | P21: =SUM(D21:I21) -> 9
C22: Holding brucellosis exposed | D22: {=SUM(IF('Consignment and Releases'!H:H="Hold Bruc Pos",'Consignment and Releases'!B:B,0))} -> 0 | E22: {=SUM(IF('Consignment and Releases'!H:H="Hold Bruc Pos",'Consignment and Releases'!C:C,0))} -> 0 | F22: {=SUM(IF('Consignment and Releases'!H:H="Hold Bruc Pos",'Consignment and Releases'!D:D,0))} -> 0 | G22: {=SUM(IF('Consignment and Releases'!H:H="Hold Bruc Pos",'Consignment and Releases'!E:E,0))} -> 0 | H22: {=SUM(IF('Consignment and Releases'!H:H="Hold Bruc Pos",'Consignment and Releases'!F:F,0))} -> 0 | I22: {=SUM(IF('Consignment and Releases'!H:H="Hold Bruc Pos",'Consignment and Releases'!G:G,0))} -> 0 | J22: 0 | K22: 0 | L22: 0 | M22: 0 | N22: 0 | O22: 0 | P22: =SUM(D22:I22) -> 0
C23: Holding brucellosis negative | D23: {=SUM(IF('Consignment and Releases'!H:H="Hold Bruc Neg",'Consignment and Releases'!B:B,0))} -> 0 | E23: {=SUM(IF('Consignment and Releases'!H:H="Hold Bruc Neg",'Consignment and Releases'!C:C,0))} -> 0 | F23: {=SUM(IF('Consignment and Releases'!H:H="Hold Bruc Neg",'Consignment and Releases'!D:D,0))} -> 0 | G23: {=SUM(IF('Consignment and Releases'!H:H="Hold Bruc Neg",'Consignment and Releases'!E:E,0))} -> 0 | H23: {=SUM(IF('Consignment and Releases'!H:H="Hold Bruc Neg",'Consignment and Releases'!F:F,0))} -> 0 | I23: {=SUM(IF('Consignment and Releases'!H:H="Hold Bruc Neg",'Consignment and Releases'!G:G,0))} -> 0 | J23: 0 | K23: 0 | L23: 0 | M23: 0 | N23: 0 | O23: 0 | P23: =SUM(D23:I23) -> 0
B24: Year to Date | C24: HARVEST | D24: =SUM(D4:D15) -> 10 | F24: =SUM(F4:F15) -> 2 | H24: =SUM(H4:H15) -> 0 | I24: =SUM(I4:I15) -> 1 | J24: =SUM(J4:J15) -> 21 | L24: =SUM(L4:L15) -> 6 | N24: =SUM(N4:N15) -> 0 | O24: =SUM(O4:O15) -> 1 | P24: =SUM(D24:O24) -> 41
C25: CULL | D25: =SUM(D16:D19) -> 6 | E25: =SUM(E16:E19) -> 2 | F25: =SUM(F16:F19) -> 7 | G25: =SUM(G16:G19) -> 1 | H25: =SUM(H16:H19) -> 0 | I25: =SUM(I16:I19) -> 4 | J25: =SUM(J16:J19) -> 0 | K25: =SUM(K16:K19) -> 0 | ... O25: =SUM(O16:O19) -> 0
C26: HOLD/RELEASED | D26: =SUM(D20:D23) -> 1 | E26: =SUM(E20:E23) -> 0 | F26: =SUM(F20:F23) -> 8 | G26: =SUM(G20:G23) -> 0 | H26: =SUM(H20:H23) -> 0 | I26: =SUM(I20:I23) -> 0 | J26: =SUM(J20:J23) -> 0 | K26: =SUM(K20:K23) -> 0 | ... O26: =SUM(O20:O23) -> 0
C27: TOTAL | D27: =SUM(D24:D26) -> 17 | E27: =SUM(E24:E26) -> 2 | F27: =SUM(F24:F26) -> 17 | G27: =SUM(G24:G26) -> 1 | H27: =SUM(H24:H26) -> 0 | I27: =SUM(I24:I26) -> 5 | J27: =SUM(J24:J26) -> 21 | K27: =SUM(K24:K26) -> 0 | ... O27: =SUM(O24:O26) -> 1
C28: =SUM(D28:O28) -> 70 | D28: =SUM(D27:I27) -> 42 | J28: =SUM(J27:O27) -> 28 | P28: =SUM(P16:P18,P24) -> 61
B29: 1 - Wounded animals shot within Yellowstone by YNP personnel
B30: 2 - Wounding loss reported by MTFWP

Sheet Harvest Log
A1: Agency/Tribe | C1: NORTH | G1: WEST
C2: Male | D2: Female | E2: Unk | G2: Male | H2: Female | I2: Unk
C3: Adult | D3: Adult | E3: Unk | F3: Calf | G3: Adult | H3: Adult | I3: Unk | J3: Calf | K3: NORTH TOTAL | L3: WEST TOTAL | M3: TOTAL | N3: Hunt Seas | P3: Numbers updated from harvest table below including all days in yellow
A4: State of Montana | C4: 0 | D4: 0 | E4: 0 | F4: 0 | K4: =SUM(C4:F4) -> 0 | L4: =SUM(G4:J4) -> 0 | M4: =SUM(C4:J4) -> 0
A5: CSKT | C5: 0 | D5: 0 | E5: 0 | F5: 0 | K5: =SUM(C5:F5) -> 0 | L5: =SUM(G5:J5) -> 0 | M5: =SUM(C5:J5) -> 0
A6: NPT | C6: 3 | D6: 1 | E6: 0 | F6: 1 | K6: =SUM(C6:F6) -> 5 | L6: =SUM(G6:J6) -> 0 | M6: =SUM(C6:J6) -> 5
A7: CTUIR | C7: 0 | D7: 0 | E7: 0 | F7: 0 | K7: =SUM(C7:F7) -> 0 | L7: =SUM(G7:J7) -> 0 | M7: =SUM(C7:J7) -> 0
A8: SB | C8: 0 | D8: 0 | E8: 0 | F8: 0 | K8: =SUM(C8:F8) -> 0 | L8: =SUM(G8:J8) -> 0 | M8: =SUM(C8:J8) -> 0
A9: YN | C9: 0 | D9: 0 | E9: 0 | F9: 0 | K9: =SUM(C9:F9) -> 0 | L9: =SUM(G9:J9) -> 0 | M9: =SUM(C9:J9) -> 0
A10: BN | C10: 0 | D10: 0 | E10: 0 | F10: 0 | K10: =SUM(C10:F10) -> 0 | L10: =SUM(G10:J10) -> 0 | M10: =SUM(C10:J10) -> 0
A11: NARAP | C11: 0 | D11: 0 | E11: 0 | F11: 0 | K11: =SUM(C11:F11) -> 0 | L11: =SUM(G11:J11) -> 0 | M11: =SUM(C11:J11) -> 0
A12: CROW | C12: 0 | D12: 0 | E12: 0 | F12: 0 | K12: =SUM(C12:F12) -> 0 | L12: =SUM(G12:J12) -> 0 | M12: =SUM(C12:J12) -> 0
A13: NPS (shot/died in park) | C13: 0 | D13: 0 | E13: 0 | F13: 0 | K13: =SUM(C13:F13) -> 0 | L13: =SUM(G13:J13) -> 0 | M13: =SUM(C13:J13) -> 0
A14: MTFWP (shot/donated/seized) | C14: 0 | D14: 0 | E14: 0 | F14: 0 | K14: =SUM(C14:F14) -> 0 | L14: =SUM(G14:J14) -> 0 | M14: =SUM(C14:J14) -> 0
A15: MTFWP (wounding loss) | C15: 0 | D15: 0 | E15: 0 | F15: 0 | K15: =SUM(C15:F15) -> 0 | L15: =SUM(G15:J15) -> 0 | M15: =SUM(C15:J15) -> 0
A16: Unreported Harvests | C16: 0 | D16: 0 | E16: 0 | F16: 0 | K16: =SUM(C16:F16) -> 0 | L16: =SUM(G16:J16) -> 0 | M16: =SUM(C16:J16) -> 0
A17: Year to Date | C17: =SUM(C4:C16) -> 3 | D17: =SUM(D4:D16) -> 1 | E17: =SUM(E4:E16) -> 0 | F17: =SUM(F4:F16) -> 1 | G17: =SUM(G4:G16) -> 0 | H17: =SUM(H4:H16) -> 0 | I17: =SUM(I4:I16) -> 0 | J17: =SUM(J4:J16) -> 0 | K17: =SUM(C17:F17) -> 5 | L17: =SUM(G17:J17) -> 0 | M17: =SUM(C17:J17) -> 5
A18: Total | C18: =SUM(C17:F17) -> 5 | G18: =SUM(G17:J17) -> 0
B19: updated: | H19: Total in Table above: | I19: =SUM((C18,G18)) -> 5
H20: Total in Harvest summary below: | I20: =SUM(G25:H164) -> 13
A21: Harvest Summary Table:
A22: **Note: This info comes primarily through a group communication text. This total is slightly less than the above MTFWP totals**
I23: HUNT BREAKDOWN BY ENTITY | T23: HUNT LOCATION
A24: Date | B24: Between Landslide and Reece | C24: Out of park maximum count | E24: Huntable | G24: Harvests | I24: STATE | J24: CSKT | K24: NPT | L24: CTUIR | M24: SB | N24: YN | O24: BN | P24: NARAP | Q24: CROW | R24: UNK | S24: NPS shot or died in park | T24: BEATTIE | U24: EAGLE SMA | V24: CORWIN | W24: CUTLER | X24: Captured | Z24: Notes
A30: 45372 | B30: 75 | C30: 0 | E30: 0 | G30: 0 | I30: 0 | J30: 0 | K30: 0 | L30: 0 | M30: 0 | N30: 0 | O30: 0 | P30: 0 | Q30: 0 | R30: 0 | S30: 0 | T30: 0 | U30: 0 | V30: 0 | W30: 0 | X30: 0
A31: 45373 | C31: 0 | E31: 0 | G31: 0 | I31: 0 | J31: 0 | K31: 0 | L31: 0 | M31: 0 | N31: 0 | O31: 0 | P31: 0 | Q31: 0 | R31: 0 | S31: 0 | T31: 0 | U31: 0 | V31: 0 | W31: 0 | X31: 29
A32: 45374 | B32: 51 | C32: 0 | E32: 0 | G32: 0 | I32: 0 | J32: 0 | K32: 0 | L32: 0 | M32: 0 | N32: 0 | O32: 0 | P32: 0 | Q32: 0 | R32: 0 | S32: 0 | T32: 0 | U32: 0 | V32: 0 | W32: 0 | X32: 0
A33: 45375 | B33: 0 | C33: 55 | E33: 55 | G33: 5 | I33: 0 | J33: 0 | K33: 5 | L33: 0 | M33: 0 | N33: 0 | O33: 0 | P33: 0 | Q33: 0 | R33: 0 | S33: 0 | T33: 5 | U33: 0 | V33: 0 | W33: 0 | X33: 0
A34: 45376 | B34: 50 | C34: 0 | E34: 0 | G34: 0 | I34: 0 | J34: 0 | K34: 0 | L34: 0 | M34: 0 | N34: 0 | O34: 0 | P34: 0 | Q34: 0 | R34: 0 | S34: 0 | T34: 0 | U34: 0 | V34: 0 | W34: 0 | X34: 0
A35: 45377 | B35: 0 | C35: 0 | E35: 0 | G35: 0 | I35: 0 | J35: 0 | K35: 0 | L35: 0 | M35: 0 | N35: 0 | O35: 0 | P35: 0 | Q35: 0 | R35: 0 | S35: 0 | T35: 0 | U35: 0 | V35: 0 | W35: 0 | X35: 0
A36: 45378 | B36: 0 | C36: 0 | E36: 0 | G36: 0 | I36: 0 | J36: 0 | K36: 0 | L36: 0 | M36: 0 | N36: 0 | O36: 0 | P36: 0 | Q36: 0 | R36: 0 | S36: 0 | T36: 0 | U36: 0 | V36: 0 | W36: 0 | X36: 0
A37: 45379 | B37: 29 | C37: 0 | E37: 0 | G37: 0 | I37: 0 | J37: 0 | K37: 0 | L37: 0 | M37: 0 | N37: 0 | O37: 0 | P37: 0 | Q37: 0 | R37: 0 | S37: 0 | T37: 0 | U37: 0 | V37: 0 | W37: 0 | X37: 0
A38: 45380 | B38: 3 | C38: 0 | E38: 0 | G38: 0 | I38: 0 | J38: 0 | K38: 0 | L38: 0 | M38: 0 | N38: 0 | O38: 0 | P38: 0 | Q38: 0 | R38: 0 | S38: 0 | T38: 0 | U38: 0 | V38: 0 | W38: 0 | X38: 0
A39: 45381 | B39: 3 | C39: 0 | E39: 0 | G39: 0 | I39: 0 | J39: 0 | K39: 0 | L39: 0 | M39: 0 | N39: 0 | O39: 0 | P39: 0 | Q39: 0 | R39: 0 | S39: 0 | T39: 0 | U39: 0 | V39: 0 | W39: 0 | X39: 0
A40: 45382 | B40: 85 | C40: 20 | E40: 20 | G40: 6 | T40: 6 | X40: 0 | Z40: Harvests 2 bulls, 3 cows, 1 calf Blackfeet/Northern Arapaho
A41: 45383 | B41: 85 | C41: 2 | E41: 2 | G41: 0 | I41: 0 | J41: 0 | K41: 0 | L41: 0 | M41: 0 | N41: 0 | O41: 0 | P41: 0 | Q41: 0 | R41: 0 | S41: 0 | T41: 0 | U41: 0 | V41: 0 | W41: 0 | X41: 0
A42: 45384 | B42: 50 | C42: 0 | E42: 0 | G42: 0 | I42: 0 | J42: 0 | K42: 0 | L42: 0 | M42: 0 | N42: 0 | O42: 0 | P42: 0 | Q42: 0 | R42: 0 | S42: 0 | T42: 0 | U42: 0 | V42: 0 | W42: 0 | X42: 0
A43: 45385 | B43: 38 | C43: 22 | E43: 22 | G43: 0 | I43: 0 | J43: 0 | K43: 0 | L43: 0 | M43: 0 | N43: 0 | O43: 0 | P43: 0 | Q43: 0 | R43: 0 | S43: 0 | T43: 0 | U43: 0 | V43: 0 | W43: 0 | X43: 0
A44: 45386 | B44: 20 | C44: 0 | E44: 0 | G44: 0 | I44: 0 | J44: 0 | K44: 0 | L44: 0 | M44: 0 | N44: 0 | O44: 0 | P44: 0 | Q44: 0 | R44: 0 | S44: 0 | T44: 0 | U44: 0 | V44: 0 | W44: 0 | X44: 0
A45: 45387 | B45: 18 | C45: 0 | E45: 0 | G45: 0 | I45: 0 | J45: 0 | K45: 0 | L45: 0 | M45: 0 | N45: 0 | O45: 0 | P45: 0 | Q45: 0 | R45: 0 | S45: 0 | T45: 0 | U45: 0 | V45: 0 | W45: 0 | X45: 0
...

Sheet Gardiner Basin Counts
H1: **Pulls from Harvest Log
A2: Date | B2: Mammoth to Gardiner *Includes Slide Lake, Mcminn, China Gardens | C2: North Entrance Station to Stephens Creek Facility *Includes Shooting Range Flats | D2: Stephens Creek Facility to Park Boundary | E2: North of Park Boundary | F2: Eagle Creek SMA | G2: Total | H2: Harvests to Date | I2: New Harvests | J2: Trapped to Date | K2: New Trapped
A3: 45299 | B3: 0 | C3: 0 | D3: 0 | E3: 0 | F3: 0 | G3: 0 | H3: 0 | I3: 0 | J3: 0 | K3: 0
A4: 45307 | B4: 0 | C4: 0 | D4: 0 | E4: 0 | F4: 0 | G4: 0 | H4: 0 | I4: 0 | J4: 0 | K4: 0
A5: 45313 | B5: 0 | C5: 0 | D5: 0 | E5: 0 | F5: 0 | G5: 0 | H5: 0 | I5: 0 | J5: 0 | K5: 0
A6: 45320 | B6: 0 | C6: 0 | D6: 0 | E6: 0 | F6: 0 | G6: 0 | H6: 0 | I6: 0 | J6: 0 | K6: 0
A7: 45327 | B7: 0 | C7: 0 | D7: 0 | E7: 0 | F7: 0 | G7: 0 | H7: 0 | I7: 0 | J7: 0 | K7: 0
A8: 45336 | B8: 0 | C8: 0 | D8: 0 | E8: 0 | F8: 0 | G8: 0 | H8: 0 | I8: 0 | J8: 0 | K8: 0
A9: 45348 | B9: 0 | C9: 0 | D9: 0 | E9: 0 | F9: 0 | G9: 0 | H9: 0 | I9: 0 | J9: 0 | K9: 0
A10: 45357 | B10: 12 | C10: 0 | D10: 0 | E10: 0 | F10: 0 | G10: 12 | H10: 0 | I10: 0 | J10: 0 | K10: 0
A11: 45363 | B11: 42 | C11: 0 | D11: 0 | E11: 0 | F11: 0 | G11: 42 | H11: 0 | I11: 0 | J11: 0 | K11: 0
A12: 45369 | B12: 54 | C12: 102 | D12: 0 | E12: 0 | F12: 0 | G12: 156 | H12: 0 | I12: 0 | J12: 0 | K12: 0
A13: 45376 | B13: 9 | C13: 58 | D13: 0 | E13: 0 | F13: 0 | G13: 67 | H13: 5 | I13: 5 | J13: 29 | K13: 29 | L13: YELL-251, YELL-268, YELL-394
A14: 45383 | B14: 7 | C14: 65 | D14: 2 | E14: 0 | F14: 0 | G14: 74 | H14: 11 | I14: 6 | J14: 20 | K14: -9
A15: 45390 | B15: 50 | C15: 121 | D15: 0 | E15: 0 | F15: 0 | G15: 171 | H15: 11 | I15: 0 | J15: 20 | K15: 0 | L15: YELL-388, YELL-394, YELL-268
A16: 45398 | B16: 36 | C16: 74 | D16: 85 | E16: 0 | F16: 0 | G16: 195 | H16: 11 | I16: 0 | J16: 20 | K16: 0 | L16: YELL-268
A17: 45406 | B17: 45 | C17: 110 | D17: 0 | E17: 0 | F17: 0 | G17: 155 | H17: 11 | I17: 0 | J17: 20 | K17: 0 | L17: YELL-268
A18: 45414 | B18: 24 | C18: 17 | D18: 0 | E18: 2 | F18: 0 | G18: 43 | H18: 13 | I18: 2 | J18: 20 | K18: 0
G22: =IF(A22<>"",SUM(B22:F22),"") | H22: =IF(A22<>"",H21+I22,"") | I22: =IF(A22<>"",INDEX('Harvest Log'!$G$25:$G$515,MATCH('Gardiner Basin Counts'!$A22,'Harvest Log'!$A$25:$A$515,0)),"") | J22: =IF(A22<>"",J21+K22,"") | K22: =IF(A22<>"",INDEX('Harvest Log'!$I$25:$I$515,MATCH('Gardiner Basin Counts'!$A22,'Harvest Log'!$A$25:$A$515,0)),"")
G23: =IF(A23<>"",SUM(B23:F23),"") | H23: =IF(A23<>"",H22+I23,"") | I23: =IF(A23<>"",INDEX('Harvest Log'!$G$25:$G$515,MATCH('Gardiner Basin Counts'!$A23,'Harvest Log'!$A$25:$A$515,0)),"") | J23: =IF(A23<>"",J22+K23,"") | K23: =IF(A23<>"",INDEX('Harvest Log'!$I$25:$I$515,MATCH('Gardiner Basin Counts'!$A23,'Harvest Log'!$A$25:$A$515,0)),"")
G24: =IF(A24<>"",SUM(B24:F24),"") | H24: =IF(A24<>"",H23+I24,"") | I24: =IF(A24<>"",INDEX('Harvest Log'!$G$25:$G$515,MATCH('Gardiner Basin Counts'!$A24,'Harvest Log'!$A$25:$A$515,0)),"") | J24: =IF(A24<>"",J23+K24,"") | K24: =IF(A24<>"",INDEX('Harvest Log'!$I$25:$I$515,MATCH('Gardiner Basin Counts'!$A24,'Harvest Log'!$A$25:$A$515,0)),"")
G25: =IF(A25<>"",SUM(B25:F25),"") | H25: =IF(A25<>"",H24+I25,"") | I25: =IF(A25<>"",INDEX('Harvest Log'!$G$25:$G$515,MATCH('Gardiner Basin Counts'!$A25,'Harvest Log'!$A$25:$A$515,0)),"") | J25: =IF(A25<>"",J24+K25,"") | K25: =IF(A25<>"",INDEX('Harvest Log'!$I$25:$I$515,MATCH('Gardiner Basin Counts'!$A25,'Harvest Log'!$A$25:$A$515,0)),"")
G26: =IF(A26<>"",SUM(B26:F26),"") | H26: =IF(A26<>"",H25+I26,"") | I26: =IF(A26<>"",INDEX('Harvest Log'!$G$25:$G$515,MATCH('Gardiner Basin Counts'!$A26,'Harvest Log'!$A$25:$A$515,0)),"") | J26: =IF(A26<>"",J25+K26,"") | K26: =IF(A26<>"",INDEX('Harvest Log'!$I$25:$I$515,MATCH('Gardiner Basin Counts'!$A26,'Harvest Log'!$A$25:$A$515,0)),"")
G27: =IF(A27<>"",SUM(B27:F27),"") | H27: =IF(A27<>"",H26+I27,"") | I27: =IF(A27<>"",INDEX('Harvest Log'!$G$25:$G$515,MATCH('Gardiner Basin Counts'!$A27,'Harvest Log'!$A$25:$A$515,0)),"") | J27: =IF(A27<>"",J26+K27,"") | K27: =IF(A27<>"",INDEX('Harvest Log'!$I$25:$I$515,MATCH('Gardiner Basin Counts'!$A27,'Harvest Log'!$A$25:$A$515,0)),"")
G28: =IF(A28<>"",SUM(B28:F28),"") | H28: =IF(A28<>"",H27+I28,"") | I28: =IF(A28<>"",INDEX('Harvest Log'!$G$25:$G$515,MATCH('Gardiner Basin Counts'!$A28,'Harvest Log'!$A$25:$A$515,0)),"") | J28: =IF(A28<>"",J27+K28,"") | K28: =IF(A28<>"",INDEX('Harvest Log'!$I$25:$I$515,MATCH('Gardiner Basin Counts'!$A28,'Harvest Log'!$A$25:$A$515,0)),"")
G29: =IF(A29<>"",SUM(B29:F29),"") | H29: =IF(A29<>"",H28+I29,"") | I29: =IF(A29<>"",INDEX('Harvest Log'!$G$25:$G$515,MATCH('Gardiner Basin Counts'!$A29,'Harvest Log'!$A$25:$A$515,0)),"") | J29: =IF(A29<>"",J28+K29,"") | K29: =IF(A29<>"",INDEX('Harvest Log'!$I$25:$I$515,MATCH('Gardiner Basin Counts'!$A29,'Harvest Log'!$A$25:$A$515,0)),"")
G30: =IF(A30<>"",SUM(B30:F30),"") | H30: =IF(A30<>"",H29+I30,"") | I30: =IF(A30<>"",INDEX('Harvest Log'!$G$25:$G$515,MATCH('Gardiner Basin Counts'!$A30,'Harvest Log'!$A$25:$A$515,0)),"") | J30: =IF(A30<>"",J29+K30,"") | K30: =IF(A30<>"",INDEX('Harvest Log'!$I$25:$I$515,MATCH('Gardiner Basin Counts'!$A30,'Harvest Log'!$A$25:$A$515,0)),"")
G31: =IF(A31<>"",SUM(B31:F31),"") | H31: =IF(A31<>"",H30+I31,"") | I31: =IF(A31<>"",INDEX('Harvest Log'!$G$25:$G$515,MATCH('Gardiner Basin Counts'!$A31,'Harvest Log'!$A$25:$A$515,0)),"") | J31: =IF(A31<>"",J30+K31,"") | K31: =IF(A31<>"",INDEX('Harvest Log'!$I$25:$I$515,MATCH('Gardiner Basin Counts'!$A31,'Harvest Log'!$A$25:$A$515,0)),"")

Sheet Bison Season Chronology
A1: Table 4. Bison Season Chronology of events
A2: Date | C2: Notes

Sheet Capture 
A1: Date | B1: Capture
A2: 45373 | B2: 29
A24: TOTAL | B24: =SUM(B2:B23) -> 29

Sheet West Hazing
B2: Date | C2: No. of Adults (brown) | D2: No. of Newborn | E2: Start | F2: Stop | G2: Marked Animals | H2: Personnel | I2: Notes
B11: Date | C11: No. of Adults (brown) | D11: No. of Newborn | E11: Start | F11: Stop | H11: Personnel

Sheet Testing
A1: Date | B1: Male | H1: Female
B2: Adult | D2: Yearling | F2: Calf | H2: Adult | J2: Yearling | L2: Calf
B3: + | C3: - | D3: + | E3: - | F3: + | G3: - | H3: + | I3: - | J3: + | K3: - | L3: + | M3: -
A4: 45377 | B4: 6 | C4: 1 | D4: 1 | E4: 1 | F4: 0 | G4: 0 | H4: 7 | I4: 6 | J4: 0 | K4: 1 | L4: 1 | M4: 3 | N4: 2 collared cows released without testing
A27: Total | B27: =SUM(B4:B26) -> 6 | C27: =SUM(C4:C26) -> 1 | D27: =SUM(D4:D26) -> 1 | E27: =SUM(E4:E26) -> 1 | F27: =SUM(F4:F26) -> 0 | G27: =SUM(G4:G26) -> 0 | H27: =SUM(H4:H26) -> 7 | I27: =SUM(I4:I26) -> 6 | ... M27: =SUM(M4:M26) -> 3
A28: Total | B28: =SUM(B27:G27) -> 9 | H28: =SUM(H3:M26) -> 18

Sheet Consignment and Releases
A1: Date | B1: Adult Male | C1: Yearling Male | D1: Adult Female | E1: Yearling Female | F1: Unknown | G1: Calf | H1: Event | I1: Slaughterhouse | J1: Notes | N1: 311 | O1: 124 | P1: 45 | Q1: 131
A2: 45378 | B2: 5 | C2: 1 | D2: 7 | E2: 0 | F2: 0 | G2: 1 | H2: Consign | I2: Tizers
A3: 45377 | B3: 1 | C3: 0 | D3: 8 | E3: 0 | F3: 0 | G3: 0 | H3: Release
A4: 45377 | B4: 1 | C4: 0 | D4: 0 | E4: 0 | F4: 0 | G4: 0 | H4: Mortality | J4: Broken leg during sorting/testing
