Workbook

Sheet Biweekly Report
B1: Bison Management Operations Winter 2021-2022:
B3: Table 1. Removal Summary. Number of Yellowstone bison removed through state and treaty harvests and culled through consignment to slaughter or quarantine facilities, or dying within containment. Table abbreviations are adult (A), yearling (Y), calf (C), and unknown sex (Unk). Harvest numbers are preliminary, in-season totals that may change.
B7: Date | C7: Removal Method | F7: NORTH | L7: WEST
F8: Male | H8: Female | J8: Unk | L8: Male | N8: Female | P8: Unk
F9: A | G9: Y | H9: A | I9: Y | J9: Unk | K9: C | L9: A | M9: Y | N9: A | O9: Y | P9: Unk | Q9: C
B10: HARVEST | C10: Harvest (Mont) | F10: 1 | G10: 0 | H10: =Harvest!D6 -> 0 | I10: 0 | J10: =Harvest!E6 -> 0 | K10: =Harvest!F6 -> 0 | L10: =Harvest!G6 -> 1 | M10: 0 | N10: =Harvest!H6 -> 0 | O10: 0 | P10: =Harvest!I6 -> 0 | Q10: =Harvest!J6 -> 0
C11: Harvest (CSKT) | E11: Harvest (CSKT) | F11: =Harvest!C7 -> 0 | G11: 0 | H11: =Harvest!D7 -> 0 | I11: 0 | J11: =Harvest!E7 -> 0 | K11: =Harvest!F7 -> 0 | L11: =Harvest!G7 -> 0 | M11: 0 | N11: =Harvest!H7 -> 0 | O11: 0 | P11: =Harvest!I7 -> 0 | Q11: =Harvest!J7 -> 0
C12: Harvest (NPT) | E12: Harvest (NPT) | F12: =Harvest!C8 -> 1 | G12: 0 | H12: =Harvest!D8 -> 0 | I12: 0 | J12: =Harvest!E8 -> 0 | K12: =Harvest!F8 -> 0 | L12: =Harvest!G8 -> 0 | M12: 0 | N12: =Harvest!H8 -> 0 | O12: 0 | P12: =Harvest!I8 -> 0 | Q12: =Harvest!J8 -> 0
C13: Harvest (CTU) | E13: Harvest (CTU) | F13: =Harvest!C9 -> 1 | G13: 0 | H13: =Harvest!D9 -> 0 | I13: 0 | J13: =Harvest!E9 -> 0 | K13: =Harvest!F9 -> 0 | L13: =Harvest!G9 -> 0 | M13: 0 | N13: =Harvest!H9 -> 0 | O13: 0 | P13: =Harvest!I9 -> 0 | Q13: =Harvest!J9 -> 0
C14: Harvest (SB) | E14: Harvest (SB) | F14: =Harvest!C10 -> 0 | G14: 0 | H14: =Harvest!D10 -> 0 | I14: 0 | J14: =Harvest!E10 -> 0 | K14: =Harvest!F10 -> 0 | L14: =Harvest!G10 -> 0 | M14: 0 | N14: =Harvest!H10 -> 0 | O14: 0 | P14: =Harvest!I10 -> 0 | Q14: =Harvest!J10 -> 0
C15: Harvest (YN) | E15: Harvest (YN) | F15: =Harvest!C11 -> 0 | G15: 0 | H15: =Harvest!D11 -> 0 | I15: 0 | J15: =Harvest!E11 -> 0 | K15: =Harvest!F11 -> 0 | L15: =Harvest!G11 -> 0 | M15: 0 | N15: =Harvest!H11 -> 0 | O15: 0 | P15: =Harvest!I11 -> 0 | Q15: =Harvest!J11 -> 0
C16: Harvest (BT) | E16: Harvest (BT) | F16: =Harvest!C12 -> 0 | G16: 0 | H16: =Harvest!D12 -> 0 | I16: 0 | J16: =Harvest!E12 -> 0 | K16: =Harvest!F12 -> 0 | L16: =Harvest!G12 -> 1 | M16: 0 | N16: =Harvest!H12 -> 5 | O16: 0 | P16: =Harvest!I12 -> 0 | Q16: =Harvest!J12 -> 0
C17: NPS1 | E17: NPS1 | F17: =Harvest!C13 -> 0 | G17: 0 | H17: =Harvest!D13 -> 3 | I17: 0 | J17: =Harvest!E13 -> 0 | K17: =Harvest!F13 -> 0 | L17: =Harvest!G13 -> 0 | M17: 0 | N17: =Harvest!H13 -> 0 | O17: 0 | P17: =Harvest!I13 -> 0 | Q17: =Harvest!J13 -> 0
C18: MTFWP2 | E18: MTFWP2 | F18: =Harvest!C14 -> 0 | G18: 0 | H18: =Harvest!D14 -> 0 | I18: 0 | J18: =Harvest!E14 -> 0 | K18: =Harvest!F14 -> 0 | L18: =Harvest!G14 -> 0 | M18: 0 | N18: =Harvest!H14 -> 0 | O18: 0 | P18: =Harvest!I14 -> 0 | Q18: =Harvest!J14 -> 0
B19: CULL | C19: Captured and Consigned3 | F19: =COUNTIFS(Trapside!F:F,"M",Trapside!G:G,"A",Trapside!P:P,"Slaughter") -> 5 | G19: =COUNTIFS(Trapside!F:F,"M",Trapside!G:G,"Y",Trapside!P:P,"Slaughter") -> 2 | H19: =COUNTIFS(Trapside!F:F,"F",Trapside!G:G,"A",Trapside!P:P,"Slaughter") -> 20 | I19: =COUNTIFS(Trapside!F:F,"F",Trapside!G:G,"Y",Trapside!P:P,"Slaughter") -> 0 | J19: 0 | K19: =COUNTIFS(Trapside!G:G,"C",Trapside!P:P,"Slaughter") -> 0 | L19: 0 | M19: 0 | N19: 0 | O19: 0 | P19: 0 | Q19: 0
C20: Removed to Quarantine | F20: =COUNTIFS(Trapside!F:F,"M",Trapside!G:G,"A",Trapside!P:P,"Quarantine") -> 0 | G20: =COUNTIFS(Trapside!F:F,"M",Trapside!G:G,"Y",Trapside!P:P,"Quarantine") -> 3 | H20: =COUNTIFS(Trapside!F:F,"F",Trapside!G:G,"A",Trapside!P:P,"Quarantine") -> 0 | I20: =COUNTIFS(Trapside!F:F,"F",Trapside!G:G,"Y",Trapside!P:P,"Quarantine") -> 1 | J20: 0 | K20: 6 | L20: 0 | M20: 0 | N20: 0 | O20: 0 | P20: 0 | Q20: 0
C21: Capture Pen Mortality | F21: 0 | G21: 0 | H21: 0 | I21: 0 | J21: 0 | K21: 0 | L21: 0 | M21: 0 | N21: 0 | O21: 0 | P21: 0 | Q21: 0
C22: MTDOL Management Shooting | F22: 0 | G22: 0 | H22: 0 | I22: 0 | J22: 0 | K22: 0 | L22: 0 | M22: 0 | N22: 0 | O22: 0 | P22: 0 | Q22: 0
B23: Year to Date | C23: HARVEST | F23: 3 | G23: =SUM(G10:G18) -> 0 | H23: =SUM(H10:H18) -> 3 | I23: =SUM(I10:I18) -> 0 | J23: =SUM(J10:J18) -> 0 | K23: =SUM(K10:K18) -> 0 | L23: =SUM(L10:L18) -> 2 | M23: =SUM(M10:M18) -> 0 | N23: =SUM(N10:N18) -> 5 | ... Q23: =SUM(Q10:Q18) -> 0
C24: CULL | F24: =SUM(F19:F21) -> 5 | G24: =SUM(G19:G21) -> 5 | H24: =SUM(H19:H21) -> 20 | I24: =SUM(I19:I21) -> 1 | J24: =SUM(J19:J22) -> 0 | K24: =SUM(K19:K21) -> 6 | L24: 0 | M24: 0 | N24: 0 | O24: 0 | P24: 0 | Q24: 0
C25: TOTAL | F25: =SUM(F23:F24) -> 8 | G25: =SUM(G23:G24) -> 5 | H25: =SUM(H23:H24) -> 23 | I25: =SUM(I23:I24) -> 1 | J25: =SUM(J23:J24) -> 0 | K25: =SUM(K23:K24) -> 6 | L25: =SUM(L23:L24) -> 2 | M25: =SUM(M23:M24) -> 0 | ... Q25: =SUM(Q23:Q24) -> 0
F26: =SUM(F25:K25) -> 43 | L26: =SUM(L25:Q25) -> 7
C27: 1 - Wounded animals shot within Yellowstone by YNP personnel
C28: 2 - Wounding loss reported by MTFWP
C29: 3 - Five bison (4C, 1MY) were captured and initially released with 4 being recaptured since previous report.
C32: Disposition of Captured Bison: | M32: Year to Date
C33: Transferred to Tribes: | M33: =SUM(F19:K19) -> 27 | O33: 128
C34: Transferred for research: | M34: 0 | O34: 0
C35: Being held for potential quarantine enrollment: | M35: =SUM(F20:K20) -> 10 | O35: 45
C36: Mortalities within the Stephens Creek Facility: | M36: 0 | O36: 0
C37: Released: | M37: 1 | O37: 0
C39: Animals being held within the Stephens Creek Facility for consignment or release | M39: 0
B43: Table 2. Brucellosis Testing Summary Test results are pending.
C45: Date | E45: Male | K45: Female
E46: Adult | G46: Yearling | I46: Calf | K46: Adult | M46: Yearling | O46: Calf
E47: + | F47: - | G47: + | H47: - | I47: + | J47: - | K47: + | L47: - | M47: + | N47: - | O47: + | P47: -
C48: =IF('[1]Testing Summary'!A5<>"",'[1]Testing Summary'!A5,"") -> 44613 | E48: =IF('[1]Testing Summary'!B5>0,'[1]Testing Summary'!B5,"") | F48: =IF('[1]Testing Summary'!C5>0,'[1]Testing Summary'!C5,"") | G48: =IF('[1]Testing Summary'!D5>0,'[1]Testing Summary'!D5,"") -> 2 | H48: =IF('[1]Testing Summary'!E5>0,'[1]Testing Summary'!E5,"") -> 3 | I48: =IF('[1]Testing Summary'!F5>0,'[1]Testing Summary'!F5,"") | J48: =IF('[1]Testing Summary'!G5>0,'[1]Testing Summary'!G5,"") | K48: =IF('[1]Testing Summary'!H5>0,'[1]Testing Summary'!H5,"") | L48: =IF('[1]Testing Summary'!I5>0,'[1]Testing Summary'!I5,"") | ... P48: =IF('[1]Testing Summary'!M5>0,'[1]Testing Summary'!M5,"") -> 2
C49: =IF('[1]Testing Summary'!A6<>"",'[1]Testing Summary'!A6,"") | E49: =IF('[1]Testing Summary'!B6>0,'[1]Testing Summary'!B6,"") | F49: =IF('[1]Testing Summary'!C6>0,'[1]Testing Summary'!C6,"") | G49: =IF('[1]Testing Summary'!D6>0,'[1]Testing Summary'!D6,"") | H49: =IF('[1]Testing Summary'!E6>0,'[1]Testing Summary'!E6,"")
C50: =IF('[1]Testing Summary'!A7<>"",'[1]Testing Summary'!A7,"") | E50: =IF('[1]Testing Summary'!B7>0,'[1]Testing Summary'!B7,"") | F50: =IF('[1]Testing Summary'!C7>0,'[1]Testing Summary'!C7,"") | G50: =IF('[1]Testing Summary'!D7>0,'[1]Testing Summary'!D7,"") | H50: =IF('[1]Testing Summary'!E7>0,'[1]Testing Summary'!E7,"")
C51: =IF('[1]Testing Summary'!A8<>"",'[1]Testing Summary'!A8,"") | E51: =IF('[1]Testing Summary'!B8>0,'[1]Testing Summary'!B8,"") | F51: =IF('[1]Testing Summary'!C8>0,'[1]Testing Summary'!C8,"") | G51: =IF('[1]Testing Summary'!D8>0,'[1]Testing Summary'!D8,"") | H51: =IF('[1]Testing Summary'!E8>0,'[1]Testing Summary'!E8,"")
...

Sheet Harvest
A2: Harvest Summary by Agency/Tribe:
A3: Agency/Tribe | C3: NORTH | G3: WEST | L3: NORTH Harvest Chronology
C4: Male | D4: Female | E4: Unk | G4: Male | H4: Female | I4: Unk | L4: Date | N4: Hunt Closure | O4: Harvests
C5: Adult | D5: Adult | E5: Unk | F5: Calf | G5: Adult | H5: Adult | I5: Unk | J5: Calf
A6: State of Montana | C6: 1 | D6: 0 | E6: 0 | F6: 0 | G6: 1 | H6: 0 | I6: 0 | J6: 0
A7: CSKT | C7: 0 | D7: 0 | E7: 0 | F7: 0 | G7: 0 | H7: 0 | I7: 0 | J7: 0
A8: NPT | C8: 1 | D8: 0 | E8: 0 | F8: 0 | G8: 0 | H8: 0 | I8: 0 | J8: 0
A9: CTU | C9: 1 | D9: 0 | E9: 0 | F9: 0 | G9: 0 | H9: 0 | I9: 0 | J9: 0
A10: SB | C10: 0 | D10: 0 | E10: 0 | F10: 0 | G10: 0 | H10: 0 | I10: 0 | J10: 0
A11: YN | C11: 0 | D11: 0 | E11: 0 | F11: 0 | G11: 0 | H11: 0 | I11: 0 | J11: 0
A12: BN | C12: 0 | D12: 0 | E12: 0 | F12: 0 | G12: 1 | H12: 5 | I12: 0 | J12: 0
A13: NPS (injured/shot) | C13: 0 | D13: 3 | E13: 0 | F13: 0 | G13: 0 | H13: 0 | I13: 0 | J13: 0
A14: MTFWP (injured/shot) | C14: 0 | D14: 0 | E14: 0 | F14: 0 | G14: 0 | H14: 0 | I14: 0 | J14: 0
A15: MTFWP (seized) | C15: 0 | D15: 0 | E15: 0 | F15: 0 | G15: 0 | H15: 0 | I15: 0 | J15: 0
A16: Wounded/Left for Waste | C16: 0 | D16: 0 | E16: 0 | F16: 0 | G16: 0 | H16: 0 | I16: 0 | J16: 0
A17: Unreported | C17: 0 | D17: 0 | E17: 0 | F17: 0 | G17: 0 | H17: 0 | I17: 0 | J17: 0
A18: Year to Date | C18: =SUM(C6:C17) -> 3 | D18: =SUM(D6:D17) -> 3 | E18: =SUM(E6:E17) -> 0 | F18: =SUM(F6:F17) -> 0 | G18: =SUM(G6:G17) -> 2 | H18: =SUM(H6:H17) -> 5 | I18: =SUM(I6:I17) -> 0 | J18: =SUM(J6:J17) -> 0
A19: Total | C19: =SUM(C18:F18) -> 6 | G19: =SUM(G18:J18) -> 7
N20: Total | O20: =SUM(O5:O19) -> 0
H21: LAST UPDATED: | I21: =TODAY() -> 45992
C22: Total counted below in Harvest Summary: | D22: =SUM(E28:E104) -> 6
A24: **Note this summary is from conversations with Brian/Kevin and other game wardens**
A26: Harvest Summary:
A27: Date | B27: Between Landslide and Reece | C27: Out of park maximum count | D27: Huntable | E27: Harvests | F27: Captured | G27: Notes
A28: general season | B28: 0 | C28: 0 | E28: 1 | F28: 0 | G28: adult male harvested during general season unknown location and date
A29: 44577 | B29: 0 | C29: 0 | E29: 1 | F29: 0 | G29: adult male harvested up Beattie Gulch
A30: 44608 | B30: 24 | C30: 0 | D30: 0 | E30: 0 | F30: 0
A31: 44609 | B31: 27 | C31: 0 | D31: 0 | E31: 0 | F31: 23
A32: 44610 | B32: 31 | C32: 0 | D32: 0 | E32: 0 | F32: 14
A33: 44611 | B33: 17 | C33: 0 | D33: 0 | E33: 0 | F33: 0
A34: 44612 | B34: 18 | C34: 0 | D34: 0 | E34: 0 | F34: 0
A35: 44613 | B35: 17 | C35: 0 | D35: 0 | E35: 0 | F35: 0
A36: 44614 | B36: 22 | C36: 0 | D36: 0 | E36: 0 | F36: 0 | G36: 4 calves released
A37: 44615 | B37: 21 | C37: 0 | D37: 0 | E37: 0 | F37: 0
A38: 44616 | B38: 22 | C38: 0 | D38: 0 | E38: 0 | F38: 0
A39: 44617 | B39: 4 | C39: 0 | D39: 0 | E39: 0 | F39: 0
A40: 44618 | B40: 9 | C40: 0 | D40: 0 | E40: 0 | F40: 0
A41: 44619 | B41: 22 | C41: 0 | D41: 0 | E41: 0 | F41: 0
A42: 44620 | B42: 4 | C42: 0 | D42: 0 | E42: 0 | F42: 0
A43: 44621 | B43: 4 | C43: 0 | D43: 0 | E43: 0 | F43: 0
...

Sheet Capture and Consignment
A1: Date | B1: Capture | C1: Consigned | D1: Hold/Release | E1: Capture Facility Death | F1: Destination
A2: 44609 | B2: 23
A3: 44609 | B3: 14
A4: 44613 | B4: 0 | C4: 0 | D4: 7 | E4: 0 | F4: 1 YM released, 6 to quarantine
A5: 44614 | B5: 0 | C5: 27 | D5: 4 | E5: 0 | F5: released 4 calves; 27 to Tizers
A6: 44648 | B6: 4 | C6: 0 | D6: 4 | E6: 0 | F6: captured the four released calves, for 10 total held

Sheet Gardiner Basin Counts
A1: Date | B1: Mammoth to Gardiner | C1: North Entrance Station to Stephens Creek Facility | D1: Stephens Creek Facility to Park Boundary | E1: North of Park Boundary | F1: Eagle Creek SMA | G1: Total | H1: Harvests to Date | I1: New Harvests | J1: Trapped to Date | K1: New Trapped | L1: Collars
A2: 44579 | B2: 20 | C2: 5 | D2: 9 | E2: 0 | F2: 0 | G2: 34 | H2: 1 | I2: 1 | J2: 0 | K2: 0 | L2: none
A3: 44594 | B3: 52 | C3: 0 | D3: 0 | E3: 0 | F3: 0 | G3: 52 | H3: 2 | I3: 0 | J3: 0 | K3: 0
A4: 44586 | B4: 0 | C4: 11 | D4: 0 | E4: 0 | F4: 0 | G4: 11 | H4: 2 | I4: 0 | J4: 0 | K4: 0
A5: 44600 | B5: 0 | C5: 21 | D5: 0 | E5: 0 | F5: 0 | G5: 21 | H5: 2 | I5: 0 | J5: 0 | K5: 0 | L5: YELL-134
A6: 44606 | B6: 6 | C6: 53 | D6: 0 | E6: 0 | F6: 0 | G6: 59 | H6: 2 | I6: 0 | J6: 0 | K6: 0 | L6: none
A7: 44609 | B7: 6 | C7: 95 | D7: 0 | E7: 0 | F7: 0 | G7: 101 | H7: 2 | I7: 0 | J7: 23 | K7: 23 | L7: YELL-149
A8: 44614 | B8: 12 | C8: 18 | D8: 0 | E8: 0 | F8: 0 | G8: 30 | H8: 2 | I8: 0 | J8: 37 | K8: 14 | L8: none
A9: 44620 | B9: 37 | C9: 36 | D9: 4 | E9: 0 | F9: 0 | G9: 77 | H9: 2 | I9: 0 | J9: 37 | K9: 0 | L9: YELL-149
A10: 44628 | B10: 11 | C10: 3 | D10: 4 | E10: 0 | F10: 0 | G10: 18 | H10: 2 | I10: 0 | J10: 37 | K10: 0 | L10: none
A11: 44635 | B11: 16 | C11: 1 | D11: 4 | E11: 0 | F11: 0 | G11: 21 | H11: 2 | I11: 0 | J11: 37 | K11: 0 | L11: YELL-145
A12: 44642 | B12: 5 | C12: 17 | D12: 4 | E12: 0 | F12: 0 | G12: 26 | H12: 3 | I12: 1 | J12: 37 | K12: 0 | L12: YELL-145
A13: 44649 | B13: 5 | C13: 30 | D13: 0 | E13: 0 | F13: 0 | G13: 35 | H13: 4 | I13: 1 | J13: 37 | K13: 0 (re-caught the four calves) | L13: YELL-145
A14: 44656 | B14: 51 | C14: 0 | D14: 0 | E14: 0 | F14: 0 | G14: 51 | H14: 4 | I14: 0 | J14: 37 | K14: 0
A15: 44664 | B15: 75 | C15: 8 | D15: 0 | E15: 0 | F15: 0 | G15: 83 | H15: 4 | I15: 0 | J15: 37 | K15: 0 | L15: YELL-134, YELL-145
A16: 44673 | B16: 45 | C16: 9 | D16: 0 | E16: 2 | F16: 0 | G16: 56 | H16: 4 | I16: 0 | J16: 37 | K16: 0 | L16: YELL-134, YELL-145
A17: 44679 | B17: 6 | C17: 3 | D17: 0 | E17: 0 | F17: 0 | G17: 9 | H17: 4 | I17: 0 | J17: 37 | K17: 0 | L17: YELL-134, YELL-145

Sheet West Hazing
B2: Date | C2: No. of Adults (brown) | D2: No. of Newborn | E2: Start | F2: Stop | G2: Marked Animals | H2: Personnel | I2: Notes
B11: Date | C11: No. of Adults (brown) | D11: No. of Newborn | E11: Start | F11: Stop | H11: Personnel

Sheet Other Gardiner Basin Obs
A1: Date | B1: Notes
A2: 44578 | B2: report from ranger Helms 5 elk harvested in eagle cr/ Travertine area putting total 25-27 confirmed elk harvests for season

Sheet Testing
A1: Date | B1: Male | H1: Female
B2: Adult | D2: Yearling | F2: Calf | H2: Adult | J2: Yearling | L2: Calf
B3: + | C3: - | D3: + | E3: - | F3: + | G3: - | H3: + | I3: - | J3: + | K3: - | L3: + | M3: -
A4: {=IF(_xlfn.UNIQUE(Trapside!B5:B1005,FALSE,FALSE)>1/1/2022,_xlfn.UNIQUE(Trapside!B5:B1005,FALSE,FALSE),"")} -> 44613 | B4: =IF(A4<>"",COUNTIFS(Trapside!F:F,"M",Trapside!G:G,"A",Trapside!AA:AA,"POSITIVE"),"") -> 0 | C4: =IF(A4<>"",COUNTIFS(Trapside!F:F,"M",Trapside!G:G,"A",Trapside!AA:AA,"NEGATIVE"),"") -> 0 | D4: =IF(A4<>"",COUNTIFS(Trapside!F:F,"M",Trapside!G:G,"Y",Trapside!AA:AA,"POSITIVE"),"") -> 2 | E4: =IF(A4<>"",COUNTIFS(Trapside!F:F,"M",Trapside!G:G,"Y",Trapside!AA:AA,"NEGATIVE"),"") -> 3 | F4: =IF(A4<>"",COUNTIFS(Trapside!F:F,"M",Trapside!G:G,"C",Trapside!AA:AA,"POSITIVE"),"") -> 0 | G4: =IF(A4<>"",COUNTIFS(Trapside!F:F,"M",Trapside!G:G,"C",Trapside!AA:AA,"NEGATIVE"),"") -> 0 | H4: =IF(A4<>"",COUNTIFS(Trapside!F:F,"F",Trapside!G:G,"A",Trapside!AA:AA,"POSITIVE"),"") -> 0 | I4: =IF(A4<>"",COUNTIFS(Trapside!F:F,"F",Trapside!G:G,"A",Trapside!AA:AA,"NEGATIVE"),"") -> 0 | J4: =IF(A4<>"",COUNTIFS(Trapside!F:F,"F",Trapside!G:G,"Y",Trapside!AA:AA,"POSITIVE"),"") -> 0 | K4: =IF(A4<>"",COUNTIFS(Trapside!F:F,"F",Trapside!G:G,"Y",Trapside!AA:AA,"NEGATIVE"),"") -> 1 | L4: =IF(A4<>"",COUNTIFS(Trapside!F:F,"F",Trapside!G:G,"C",Trapside!AA:AA,"POSITIVE"),"") -> 1 | M4: =IF(A4<>"",COUNTIFS(Trapside!F:F,"F",Trapside!G:G,"C",Trapside!AA:AA,"NEGATIVE"),"") -> 2
B5: =IF(A5<>"",COUNTIFS(Trapside!F:F,"M",Trapside!G:G,"A",Trapside!AA:AA,"POSITIVE"),"") | C5: =IF(A5<>"",COUNTIFS(Trapside!F:F,"M",Trapside!G:G,"A",Trapside!AA:AA,"NEGATIVE"),"") | D5: =IF(A5<>"",COUNTIFS(Trapside!F:F,"M",Trapside!G:G,"Y",Trapside!AA:AA,"POSITIVE"),"") | E5: =IF(A5<>"",COUNTIFS(Trapside!F:F,"M",Trapside!G:G,"Y",Trapside!AA:AA,"NEGATIVE"),"") | F5: =IF(A5<>"",COUNTIFS(Trapside!F:F,"M",Trapside!G:G,"C",Trapside!AA:AA,"POSITIVE"),"") | G5: =IF(A5<>"",COUNTIFS(Trapside!F:F,"M",Trapside!G:G,"C",Trapside!AA:AA,"NEGATIVE"),"") | H5: =IF(A5<>"",COUNTIFS(Trapside!F:F,"F",Trapside!G:G,"A",Trapside!AA:AA,"POSITIVE"),"") | I5: =IF(A5<>"",COUNTIFS(Trapside!F:F,"F",Trapside!G:G,"A",Trapside!AA:AA,"NEGATIVE"),"") | J5: =IF(A5<>"",COUNTIFS(Trapside!F:F,"F",Trapside!G:G,"Y",Trapside!AA:AA,"POSITIVE"),"") | K5: =IF(A5<>"",COUNTIFS(Trapside!F:F,"F",Trapside!G:G,"Y",Trapside!AA:AA,"NEGATIVE"),"") | L5: =IF(A5<>"",COUNTIFS(Trapside!F:F,"F",Trapside!G:G,"C",Trapside!AA:AA,"POSITIVE"),"") | M5: =IF(A5<>"",COUNTIFS(Trapside!F:F,"F",Trapside!G:G,"C",Trapside!AA:AA,"NEGATIVE"),"")
B6: =IF(A6<>"",COUNTIFS(Trapside!F:F,"M",Trapside!G:G,"A",Trapside!AA:AA,"POSITIVE"),"") | C6: =IF(A6<>"",COUNTIFS(Trapside!F:F,"M",Trapside!G:G,"A",Trapside!AA:AA,"NEGATIVE"),"") | D6: =IF(A6<>"",COUNTIFS(Trapside!F:F,"M",Trapside!G:G,"Y",Trapside!AA:AA,"POSITIVE"),"") | E6: =IF(A6<>"",COUNTIFS(Trapside!F:F,"M",Trapside!G:G,"Y",Trapside!AA:AA,"NEGATIVE"),"") | F6: =IF(A6<>"",COUNTIFS(Trapside!F:F,"M",Trapside!G:G,"C",Trapside!AA:AA,"POSITIVE"),"") | G6: =IF(A6<>"",COUNTIFS(Trapside!F:F,"M",Trapside!G:G,"C",Trapside!AA:AA,"NEGATIVE"),"") | H6: =IF(A6<>"",COUNTIFS(Trapside!F:F,"F",Trapside!G:G,"A",Trapside!AA:AA,"POSITIVE"),"") | I6: =IF(A6<>"",COUNTIFS(Trapside!F:F,"F",Trapside!G:G,"A",Trapside!AA:AA,"NEGATIVE"),"") | J6: =IF(A6<>"",COUNTIFS(Trapside!F:F,"F",Trapside!G:G,"Y",Trapside!AA:AA,"POSITIVE"),"") | K6: =IF(A6<>"",COUNTIFS(Trapside!F:F,"F",Trapside!G:G,"Y",Trapside!AA:AA,"NEGATIVE"),"") | L6: =IF(A6<>"",COUNTIFS(Trapside!F:F,"F",Trapside!G:G,"C",Trapside!AA:AA,"POSITIVE"),"") | M6: =IF(A6<>"",COUNTIFS(Trapside!F:F,"F",Trapside!G:G,"C",Trapside!AA:AA,"NEGATIVE"),"")
B7: =IF(A7<>"",COUNTIFS(Trapside!F:F,"M",Trapside!G:G,"A",Trapside!AA:AA,"POSITIVE"),"") | C7: =IF(A7<>"",COUNTIFS(Trapside!F:F,"M",Trapside!G:G,"A",Trapside!AA:AA,"NEGATIVE"),"") | D7: =IF(A7<>"",COUNTIFS(Trapside!F:F,"M",Trapside!G:G,"Y",Trapside!AA:AA,"POSITIVE"),"") | E7: =IF(A7<>"",COUNTIFS(Trapside!F:F,"M",Trapside!G:G,"Y",Trapside!AA:AA,"NEGATIVE"),"") | F7: =IF(A7<>"",COUNTIFS(Trapside!F:F,"M",Trapside!G:G,"C",Trapside!AA:AA,"POSITIVE"),"") | G7: =IF(A7<>"",COUNTIFS(Trapside!F:F,"M",Trapside!G:G,"C",Trapside!AA:AA,"NEGATIVE"),"") | H7: =IF(A7<>"",COUNTIFS(Trapside!F:F,"F",Trapside!G:G,"A",Trapside!AA:AA,"POSITIVE"),"") | I7: =IF(A7<>"",COUNTIFS(Trapside!F:F,"F",Trapside!G:G,"A",Trapside!AA:AA,"NEGATIVE"),"") | J7: =IF(A7<>"",COUNTIFS(Trapside!F:F,"F",Trapside!G:G,"Y",Trapside!AA:AA,"POSITIVE"),"") | K7: =IF(A7<>"",COUNTIFS(Trapside!F:F,"F",Trapside!G:G,"Y",Trapside!AA:AA,"NEGATIVE"),"") | L7: =IF(A7<>"",COUNTIFS(Trapside!F:F,"F",Trapside!G:G,"C",Trapside!AA:AA,"POSITIVE"),"") | M7: =IF(A7<>"",COUNTIFS(Trapside!F:F,"F",Trapside!G:G,"C",Trapside!AA:AA,"NEGATIVE"),"")
B8: =IF(A8<>"",COUNTIFS(Trapside!F:F,"M",Trapside!G:G,"A",Trapside!AA:AA,"POSITIVE"),"") | C8: =IF(A8<>"",COUNTIFS(Trapside!F:F,"M",Trapside!G:G,"A",Trapside!AA:AA,"NEGATIVE"),"") | D8: =IF(A8<>"",COUNTIFS(Trapside!F:F,"M",Trapside!G:G,"Y",Trapside!AA:AA,"POSITIVE"),"") | E8: =IF(A8<>"",COUNTIFS(Trapside!F:F,"M",Trapside!G:G,"Y",Trapside!AA:AA,"NEGATIVE"),"") | F8: =IF(A8<>"",COUNTIFS(Trapside!F:F,"M",Trapside!G:G,"C",Trapside!AA:AA,"POSITIVE"),"") | G8: =IF(A8<>"",COUNTIFS(Trapside!F:F,"M",Trapside!G:G,"C",Trapside!AA:AA,"NEGATIVE"),"") | H8: =IF(A8<>"",COUNTIFS(Trapside!F:F,"F",Trapside!G:G,"A",Trapside!AA:AA,"POSITIVE"),"") | I8: =IF(A8<>"",COUNTIFS(Trapside!F:F,"F",Trapside!G:G,"A",Trapside!AA:AA,"NEGATIVE"),"") | J8: =IF(A8<>"",COUNTIFS(Trapside!F:F,"F",Trapside!G:G,"Y",Trapside!AA:AA,"POSITIVE"),"") | K8: =IF(A8<>"",COUNTIFS(Trapside!F:F,"F",Trapside!G:G,"Y",Trapside!AA:AA,"NEGATIVE"),"") | L8: =IF(A8<>"",COUNTIFS(Trapside!F:F,"F",Trapside!G:G,"C",Trapside!AA:AA,"POSITIVE"),"") | M8: =IF(A8<>"",COUNTIFS(Trapside!F:F,"F",Trapside!G:G,"C",Trapside!AA:AA,"NEGATIVE"),"")
B9: =IF(A9<>"",COUNTIFS(Trapside!F:F,"M",Trapside!G:G,"A",Trapside!AA:AA,"POSITIVE"),"") | C9: =IF(A9<>"",COUNTIFS(Trapside!F:F,"M",Trapside!G:G,"A",Trapside!AA:AA,"NEGATIVE"),"") | D9: =IF(A9<>"",COUNTIFS(Trapside!F:F,"M",Trapside!G:G,"Y",Trapside!AA:AA,"POSITIVE"),"") | E9: =IF(A9<>"",COUNTIFS(Trapside!F:F,"M",Trapside!G:G,"Y",Trapside!AA:AA,"NEGATIVE"),"") | F9: =IF(A9<>"",COUNTIFS(Trapside!F:F,"M",Trapside!G:G,"C",Trapside!AA:AA,"POSITIVE"),"") | G9: =IF(A9<>"",COUNTIFS(Trapside!F:F,"M",Trapside!G:G,"C",Trapside!AA:AA,"NEGATIVE"),"") | H9: =IF(A9<>"",COUNTIFS(Trapside!F:F,"F",Trapside!G:G,"A",Trapside!AA:AA,"POSITIVE"),"") | I9: =IF(A9<>"",COUNTIFS(Trapside!F:F,"F",Trapside!G:G,"A",Trapside!AA:AA,"NEGATIVE"),"") | J9: =IF(A9<>"",COUNTIFS(Trapside!F:F,"F",Trapside!G:G,"Y",Trapside!AA:AA,"POSITIVE"),"") | K9: =IF(A9<>"",COUNTIFS(Trapside!F:F,"F",Trapside!G:G,"Y",Trapside!AA:AA,"NEGATIVE"),"") | L9: =IF(A9<>"",COUNTIFS(Trapside!F:F,"F",Trapside!G:G,"C",Trapside!AA:AA,"POSITIVE"),"") | M9: =IF(A9<>"",COUNTIFS(Trapside!F:F,"F",Trapside!G:G,"C",Trapside!AA:AA,"NEGATIVE"),"")
B10: =IF(A10<>"",COUNTIFS(Trapside!F:F,"M",Trapside!G:G,"A",Trapside!AA:AA,"POSITIVE"),"") | C10: =IF(A10<>"",COUNTIFS(Trapside!F:F,"M",Trapside!G:G,"A",Trapside!AA:AA,"NEGATIVE"),"") | D10: =IF(A10<>"",COUNTIFS(Trapside!F:F,"M",Trapside!G:G,"Y",Trapside!AA:AA,"POSITIVE"),"") | E10: =IF(A10<>"",COUNTIFS(Trapside!F:F,"M",Trapside!G:G,"Y",Trapside!AA:AA,"NEGATIVE"),"") | F10: =IF(A10<>"",COUNTIFS(Trapside!F:F,"M",Trapside!G:G,"C",Trapside!AA:AA,"POSITIVE"),"") | G10: =IF(A10<>"",COUNTIFS(Trapside!F:F,"M",Trapside!G:G,"C",Trapside!AA:AA,"NEGATIVE"),"") | H10: =IF(A10<>"",COUNTIFS(Trapside!F:F,"F",Trapside!G:G,"A",Trapside!AA:AA,"POSITIVE"),"") | I10: =IF(A10<>"",COUNTIFS(Trapside!F:F,"F",Trapside!G:G,"A",Trapside!AA:AA,"NEGATIVE"),"") | J10: =IF(A10<>"",COUNTIFS(Trapside!F:F,"F",Trapside!G:G,"Y",Trapside!AA:AA,"POSITIVE"),"") | K10: =IF(A10<>"",COUNTIFS(Trapside!F:F,"F",Trapside!G:G,"Y",Trapside!AA:AA,"NEGATIVE"),"") | L10: =IF(A10<>"",COUNTIFS(Trapside!F:F,"F",Trapside!G:G,"C",Trapside!AA:AA,"POSITIVE"),"") | M10: =IF(A10<>"",COUNTIFS(Trapside!F:F,"F",Trapside!G:G,"C",Trapside!AA:AA,"NEGATIVE"),"")
B11: =IF(A11<>"",COUNTIFS(Trapside!F:F,"M",Trapside!G:G,"A",Trapside!AA:AA,"POSITIVE"),"") | C11: =IF(A11<>"",COUNTIFS(Trapside!F:F,"M",Trapside!G:G,"A",Trapside!AA:AA,"NEGATIVE"),"") | D11: =IF(A11<>"",COUNTIFS(Trapside!F:F,"M",Trapside!G:G,"Y",Trapside!AA:AA,"POSITIVE"),"") | E11: =IF(A11<>"",COUNTIFS(Trapside!F:F,"M",Trapside!G:G,"Y",Trapside!AA:AA,"NEGATIVE"),"") | F11: =IF(A11<>"",COUNTIFS(Trapside!F:F,"M",Trapside!G:G,"C",Trapside!AA:AA,"POSITIVE"),"") | G11: =IF(A11<>"",COUNTIFS(Trapside!F:F,"M",Trapside!G:G,"C",Trapside!AA:AA,"NEGATIVE"),"") | H11: =IF(A11<>"",COUNTIFS(Trapside!F:F,"F",Trapside!G:G,"A",Trapside!AA:AA,"POSITIVE"),"") | I11: =IF(A11<>"",COUNTIFS(Trapside!F:F,"F",Trapside!G:G,"A",Trapside!AA:AA,"NEGATIVE"),"") | J11: =IF(A11<>"",COUNTIFS(Trapside!F:F,"F",Trapside!G:G,"Y",Trapside!AA:AA,"POSITIVE"),"") | K11: =IF(A11<>"",COUNTIFS(Trapside!F:F,"F",Trapside!G:G,"Y",Trapside!AA:AA,"NEGATIVE"),"") | L11: =IF(A11<>"",COUNTIFS(Trapside!F:F,"F",Trapside!G:G,"C",Trapside!AA:AA,"POSITIVE"),"") | M11: =IF(A11<>"",COUNTIFS(Trapside!F:F,"F",Trapside!G:G,"C",Trapside!AA:AA,"NEGATIVE"),"")
B12: =IF(A12<>"",COUNTIFS(Trapside!F:F,"M",Trapside!G:G,"A",Trapside!AA:AA,"POSITIVE"),"") | C12: =IF(A12<>"",COUNTIFS(Trapside!F:F,"M",Trapside!G:G,"A",Trapside!AA:AA,"NEGATIVE"),"") | D12: =IF(A12<>"",COUNTIFS(Trapside!F:F,"M",Trapside!G:G,"Y",Trapside!AA:AA,"POSITIVE"),"") | E12: =IF(A12<>"",COUNTIFS(Trapside!F:F,"M",Trapside!G:G,"Y",Trapside!AA:AA,"NEGATIVE"),"") | F12: =IF(A12<>"",COUNTIFS(Trapside!F:F,"M",Trapside!G:G,"C",Trapside!AA:AA,"POSITIVE"),"") | G12: =IF(A12<>"",COUNTIFS(Trapside!F:F,"M",Trapside!G:G,"C",Trapside!AA:AA,"NEGATIVE"),"") | H12: =IF(A12<>"",COUNTIFS(Trapside!F:F,"F",Trapside!G:G,"A",Trapside!AA:AA,"POSITIVE"),"") | I12: =IF(A12<>"",COUNTIFS(Trapside!F:F,"F",Trapside!G:G,"A",Trapside!AA:AA,"NEGATIVE"),"") | J12: =IF(A12<>"",COUNTIFS(Trapside!F:F,"F",Trapside!G:G,"Y",Trapside!AA:AA,"POSITIVE"),"") | K12: =IF(A12<>"",COUNTIFS(Trapside!F:F,"F",Trapside!G:G,"Y",Trapside!AA:AA,"NEGATIVE"),"") | L12: =IF(A12<>"",COUNTIFS(Trapside!F:F,"F",Trapside!G:G,"C",Trapside!AA:AA,"POSITIVE"),"") | M12: =IF(A12<>"",COUNTIFS(Trapside!F:F,"F",Trapside!G:G,"C",Trapside!AA:AA,"NEGATIVE"),"")
B13: =IF(A13<>"",COUNTIFS(Trapside!F:F,"M",Trapside!G:G,"A",Trapside!AA:AA,"POSITIVE"),"") | C13: =IF(A13<>"",COUNTIFS(Trapside!F:F,"M",Trapside!G:G,"A",Trapside!AA:AA,"NEGATIVE"),"") | D13: =IF(A13<>"",COUNTIFS(Trapside!F:F,"M",Trapside!G:G,"Y",Trapside!AA:AA,"POSITIVE"),"") | E13: =IF(A13<>"",COUNTIFS(Trapside!F:F,"M",Trapside!G:G,"Y",Trapside!AA:AA,"NEGATIVE"),"") | F13: =IF(A13<>"",COUNTIFS(Trapside!F:F,"M",Trapside!G:G,"C",Trapside!AA:AA,"POSITIVE"),"") | G13: =IF(A13<>"",COUNTIFS(Trapside!F:F,"M",Trapside!G:G,"C",Trapside!AA:AA,"NEGATIVE"),"") | H13: =IF(A13<>"",COUNTIFS(Trapside!F:F,"F",Trapside!G:G,"A",Trapside!AA:AA,"POSITIVE"),"") | I13: =IF(A13<>"",COUNTIFS(Trapside!F:F,"F",Trapside!G:G,"A",Trapside!AA:AA,"NEGATIVE"),"") | J13: =IF(A13<>"",COUNTIFS(Trapside!F:F,"F",Trapside!G:G,"Y",Trapside!AA:AA,"POSITIVE"),"") | K13: =IF(A13<>"",COUNTIFS(Trapside!F:F,"F",Trapside!G:G,"Y",Trapside!AA:AA,"NEGATIVE"),"") | L13: =IF(A13<>"",COUNTIFS(Trapside!F:F,"F",Trapside!G:G,"C",Trapside!AA:AA,"POSITIVE"),"") | M13: =IF(A13<>"",COUNTIFS(Trapside!F:F,"F",Trapside!G:G,"C",Trapside!AA:AA,"NEGATIVE"),"")
B14: =IF(A14<>"",COUNTIFS(Trapside!F:F,"M",Trapside!G:G,"A",Trapside!AA:AA,"POSITIVE"),"") | C14: =IF(A14<>"",COUNTIFS(Trapside!F:F,"M",Trapside!G:G,"A",Trapside!AA:AA,"NEGATIVE"),"") | D14: =IF(A14<>"",COUNTIFS(Trapside!F:F,"M",Trapside!G:G,"Y",Trapside!AA:AA,"POSITIVE"),"") | E14: =IF(A14<>"",COUNTIFS(Trapside!F:F,"M",Trapside!G:G,"Y",Trapside!AA:AA,"NEGATIVE"),"") | F14: =IF(A14<>"",COUNTIFS(Trapside!F:F,"M",Trapside!G:G,"C",Trapside!AA:AA,"POSITIVE"),"") | G14: =IF(A14<>"",COUNTIFS(Trapside!F:F,"M",Trapside!G:G,"C",Trapside!AA:AA,"NEGATIVE"),"") | H14: =IF(A14<>"",COUNTIFS(Trapside!F:F,"F",Trapside!G:G,"A",Trapside!AA:AA,"POSITIVE"),"") | I14: =IF(A14<>"",COUNTIFS(Trapside!F:F,"F",Trapside!G:G,"A",Trapside!AA:AA,"NEGATIVE"),"") | J14: =IF(A14<>"",COUNTIFS(Trapside!F:F,"F",Trapside!G:G,"Y",Trapside!AA:AA,"POSITIVE"),"") | K14: =IF(A14<>"",COUNTIFS(Trapside!F:F,"F",Trapside!G:G,"Y",Trapside!AA:AA,"NEGATIVE"),"") | L14: =IF(A14<>"",COUNTIFS(Trapside!F:F,"F",Trapside!G:G,"C",Trapside!AA:AA,"POSITIVE"),"") | M14: =IF(A14<>"",COUNTIFS(Trapside!F:F,"F",Trapside!G:G,"C",Trapside!AA:AA,"NEGATIVE"),"")
B15: =IF(A15<>"",COUNTIFS(Trapside!F:F,"M",Trapside!G:G,"A",Trapside!AA:AA,"POSITIVE"),"") | C15: =IF(A15<>"",COUNTIFS(Trapside!F:F,"M",Trapside!G:G,"A",Trapside!AA:AA,"NEGATIVE"),"") | D15: =IF(A15<>"",COUNTIFS(Trapside!F:F,"M",Trapside!G:G,"Y",Trapside!AA:AA,"POSITIVE"),"") | E15: =IF(A15<>"",COUNTIFS(Trapside!F:F,"M",Trapside!G:G,"Y",Trapside!AA:AA,"NEGATIVE"),"") | F15: =IF(A15<>"",COUNTIFS(Trapside!F:F,"M",Trapside!G:G,"C",Trapside!AA:AA,"POSITIVE"),"") | G15: =IF(A15<>"",COUNTIFS(Trapside!F:F,"M",Trapside!G:G,"C",Trapside!AA:AA,"NEGATIVE"),"") | H15: =IF(A15<>"",COUNTIFS(Trapside!F:F,"F",Trapside!G:G,"A",Trapside!AA:AA,"POSITIVE"),"") | I15: =IF(A15<>"",COUNTIFS(Trapside!F:F,"F",Trapside!G:G,"A",Trapside!AA:AA,"NEGATIVE"),"") | J15: =IF(A15<>"",COUNTIFS(Trapside!F:F,"F",Trapside!G:G,"Y",Trapside!AA:AA,"POSITIVE"),"") | K15: =IF(A15<>"",COUNTIFS(Trapside!F:F,"F",Trapside!G:G,"Y",Trapside!AA:AA,"NEGATIVE"),"") | L15: =IF(A15<>"",COUNTIFS(Trapside!F:F,"F",Trapside!G:G,"C",Trapside!AA:AA,"POSITIVE"),"") | M15: =IF(A15<>"",COUNTIFS(Trapside!F:F,"F",Trapside!G:G,"C",Trapside!AA:AA,"NEGATIVE"),"")
B16: =IF(A16<>"",COUNTIFS(Trapside!F:F,"M",Trapside!G:G,"A",Trapside!AA:AA,"POSITIVE"),"") | C16: =IF(A16<>"",COUNTIFS(Trapside!F:F,"M",Trapside!G:G,"A",Trapside!AA:AA,"NEGATIVE"),"") | D16: =IF(A16<>"",COUNTIFS(Trapside!F:F,"M",Trapside!G:G,"Y",Trapside!AA:AA,"POSITIVE"),"") | E16: =IF(A16<>"",COUNTIFS(Trapside!F:F,"M",Trapside!G:G,"Y",Trapside!AA:AA,"NEGATIVE"),"") | F16: =IF(A16<>"",COUNTIFS(Trapside!F:F,"M",Trapside!G:G,"C",Trapside!AA:AA,"POSITIVE"),"") | G16: =IF(A16<>"",COUNTIFS(Trapside!F:F,"M",Trapside!G:G,"C",Trapside!AA:AA,"NEGATIVE"),"") | H16: =IF(A16<>"",COUNTIFS(Trapside!F:F,"F",Trapside!G:G,"A",Trapside!AA:AA,"POSITIVE"),"") | I16: =IF(A16<>"",COUNTIFS(Trapside!F:F,"F",Trapside!G:G,"A",Trapside!AA:AA,"NEGATIVE"),"") | J16: =IF(A16<>"",COUNTIFS(Trapside!F:F,"F",Trapside!G:G,"Y",Trapside!AA:AA,"POSITIVE"),"") | K16: =IF(A16<>"",COUNTIFS(Trapside!F:F,"F",Trapside!G:G,"Y",Trapside!AA:AA,"NEGATIVE"),"") | L16: =IF(A16<>"",COUNTIFS(Trapside!F:F,"F",Trapside!G:G,"C",Trapside!AA:AA,"POSITIVE"),"") | M16: =IF(A16<>"",COUNTIFS(Trapside!F:F,"F",Trapside!G:G,"C",Trapside!AA:AA,"NEGATIVE"),"")
B17: =IF(A17<>"",COUNTIFS(Trapside!F:F,"M",Trapside!G:G,"A",Trapside!AA:AA,"POSITIVE"),"") | C17: =IF(A17<>"",COUNTIFS(Trapside!F:F,"M",Trapside!G:G,"A",Trapside!AA:AA,"NEGATIVE"),"") | D17: =IF(A17<>"",COUNTIFS(Trapside!F:F,"M",Trapside!G:G,"Y",Trapside!AA:AA,"POSITIVE"),"") | E17: =IF(A17<>"",COUNTIFS(Trapside!F:F,"M",Trapside!G:G,"Y",Trapside!AA:AA,"NEGATIVE"),"") | F17: =IF(A17<>"",COUNTIFS(Trapside!F:F,"M",Trapside!G:G,"C",Trapside!AA:AA,"POSITIVE"),"") | G17: =IF(A17<>"",COUNTIFS(Trapside!F:F,"M",Trapside!G:G,"C",Trapside!AA:AA,"NEGATIVE"),"") | H17: =IF(A17<>"",COUNTIFS(Trapside!F:F,"F",Trapside!G:G,"A",Trapside!AA:AA,"POSITIVE"),"") | I17: =IF(A17<>"",COUNTIFS(Trapside!F:F,"F",Trapside!G:G,"A",Trapside!AA:AA,"NEGATIVE"),"") | J17: =IF(A17<>"",COUNTIFS(Trapside!F:F,"F",Trapside!G:G,"Y",Trapside!AA:AA,"POSITIVE"),"") | K17: =IF(A17<>"",COUNTIFS(Trapside!F:F,"F",Trapside!G:G,"Y",Trapside!AA:AA,"NEGATIVE"),"") | L17: =IF(A17<>"",COUNTIFS(Trapside!F:F,"F",Trapside!G:G,"C",Trapside!AA:AA,"POSITIVE"),"") | M17: =IF(A17<>"",COUNTIFS(Trapside!F:F,"F",Trapside!G:G,"C",Trapside!AA:AA,"NEGATIVE"),"")
A18: Total | B18: =SUM(B4:B17) -> 0 | C18: =SUM(C4:C17) -> 0 | D18: =SUM(D4:D17) -> 2 | E18: =SUM(E4:E17) -> 3 | F18: =SUM(F4:F17) -> 0 | G18: =SUM(G4:G17) -> 0 | H18: =SUM(H4:H17) -> 0 | I18: =SUM(I4:I17) -> 0 | ... M18: =SUM(M4:M17) -> 2
A19: Total | B19: =SUM(B3:G17) -> 5 | H19: =SUM(H3:M17) -> 4

Sheet Trapside
A1: Animal No. | B1: Date | C1: Backtag | D1: SilverID | E1: RFID | F1: Sex | G1: Age Class | H1: Blood Tube No. | I1: Pen | J1: Age | K1: Tooth | L1: Weight | M1: BCS | N1: LLW | O1: Notes | P1: Disposition | Q1: Neg Avg1 | R1: Raw FP1 | S1: Neg Avg2 | T1: Raw FP2 | U1: FP1 | V1: FP2 | W1: FPAVG | X1: FPA | Y1: CARD | Z1: BAPA | AA1: SEROLOGY | AB1: DESTINATION
A2: Bison_02/21/2022_001 | B2: 44613 | C2: 81HL6101 | D2: 81BEV8306 | E2: NA | F2: M | G2: Y | H2: 1 | I2: 2 | J2: NA | K2: NA | L2: 630 | M2: NA | N2: NA | P2: Quarantine | Q2: =AVERAGE(83.7,85.6,83.4) -> 84.233333 | S2: =AVERAGE(83.7,85.6,83.4) -> 84.233333 | T2: 83.4 | V2: =T2-S2 -> -0.83333333 | W2: =AVERAGE(U2,V2) -> -0.83333333 | X2: =IFERROR(IF(W2<10,"NEGATIVE",IF(W2>20,"POSITIVE","SUSPECT")),"") -> NEGATIVE | Y2: NEGATIVE | Z2: NEGATIVE | AA2: =IF(X2="POSITIVE","POSITIVE",IF(Y2="POSITIVE","POSITIVE",IF(Z2="POSITIVE","POSITIVE","NEGATIVE"))) -> NEGATIVE | AB2: Stephens Creek
A3: Bison_02/21/2022_002 | B3: 44613 | C3: 81HL6102 | D3: 81BEV8307 | E3: NA | F3: F | G3: Y | H3: 2 | I3: 2 | J3: NA | K3: NA | L3: 630 | M3: NA | N3: NA | P3: Quarantine | Q3: =AVERAGE(83.7,85.6,83.4) -> 84.233333 | R3: 84.1 | S3: =AVERAGE(83.7,85.6,83.4) -> 84.233333 | T3: 80.7 | U3: =R3-Q3 -> -0.13333333 | V3: =T3-S3 -> -3.5333333 | W3: =AVERAGE(U3,V3) -> -1.8333333 | X3: =IFERROR(IF(W3<10,"NEGATIVE",IF(W3>20,"POSITIVE","SUSPECT")),"") -> NEGATIVE | Y3: NEGATIVE | Z3: NEGATIVE | AA3: =IF(X3="POSITIVE","POSITIVE",IF(Y3="POSITIVE","POSITIVE",IF(Z3="POSITIVE","POSITIVE","NEGATIVE"))) -> NEGATIVE | AB3: Stephens Creek
A4: Bison_02/21/2022_003 | B4: 44613 | C4: 81HL6103 | D4: 81BEV8308 | E4: NA | F4: M | G4: Y | H4: 3 | I4: 2 | J4: NA | K4: NA | L4: 730 | M4: NA | N4: NA | P4: Quarantine | Q4: =AVERAGE(83.7,85.6,83.4) -> 84.233333 | R4: 80.2 | S4: =AVERAGE(83.7,85.6,83.4) -> 84.233333 | T4: 82.6 | U4: =R4-Q4 -> -4.0333333 | V4: =T4-S4 -> -1.6333333 | W4: =AVERAGE(U4,V4) -> -2.8333333 | X4: =IFERROR(IF(W4<10,"NEGATIVE",IF(W4>20,"POSITIVE","SUSPECT")),"") -> NEGATIVE | Y4: NEGATIVE | Z4: NEGATIVE | AA4: =IF(X4="POSITIVE","POSITIVE",IF(Y4="POSITIVE","POSITIVE",IF(Z4="POSITIVE","POSITIVE","NEGATIVE"))) -> NEGATIVE | AB4: Stephens Creek
A5: Bison_02/21/2022_004 | B5: 44613 | C5: 81HL6104 | D5: 81BEV8309 | E5: NA | F5: M | G5: Y | H5: 4 | I5: 2 | J5: NA | K5: NA | L5: 640 | M5: NA | N5: NA | P5: Slaughter | Q5: =AVERAGE(83.7,85.6,83.4) -> 84.233333 | R5: 228.2 | S5: =AVERAGE(83.7,85.6,83.4) -> 84.233333 | T5: 233.2 | U5: =R5-Q5 -> 143.96667 | V5: =T5-S5 -> 148.96667 | W5: =AVERAGE(U5,V5) -> 146.46667 | X5: =IFERROR(IF(W5<10,"NEGATIVE",IF(W5>20,"POSITIVE","SUSPECT")),"") -> POSITIVE | Y5: POSITIVE | Z5: POSITIVE | AA5: =IF(X5="POSITIVE","POSITIVE",IF(Y5="POSITIVE","POSITIVE",IF(Z5="POSITIVE","POSITIVE","NEGATIVE"))) -> POSITIVE | AB5: Tizers
A6: Bison_02/21/2022_005 | B6: 44613 | C6: 81HL6105 | D6: 81BEV8310 | E6: NA | F6: M | G6: Y | H6: 5 | I6: 2 | J6: NA | K6: NA | L6: 600 | M6: NA | N6: NA | P6: Slaughter | Q6: =AVERAGE(83.7,85.6,83.4) -> 84.233333 | R6: 202.3 | S6: =AVERAGE(83.7,85.6,83.4) -> 84.233333 | T6: 206.2 | U6: =R6-Q6 -> 118.06667 | V6: =T6-S6 -> 121.96667 | W6: =AVERAGE(U6,V6) -> 120.01667 | X6: =IFERROR(IF(W6<10,"NEGATIVE",IF(W6>20,"POSITIVE","SUSPECT")),"") -> POSITIVE | Y6: POSITIVE | Z6: NEGATIVE | AA6: =IF(X6="POSITIVE","POSITIVE",IF(Y6="POSITIVE","POSITIVE",IF(Z6="POSITIVE","POSITIVE","NEGATIVE"))) -> POSITIVE | AB6: Tizers
A7: Bison_02/21/2022_006 | B7: 44613 | C7: 81HL6106 | D7: 81BEV8311 | E7: NA | F7: F | G7: C | H7: 6 | I7: 1 | J7: NA | K7: NA | L7: 400 | M7: NA | N7: NA | P7: Quarantine | Q7: =AVERAGE(83.7,85.6,83.4) -> 84.233333 | R7: 83.4 | S7: =AVERAGE(83.7,85.6,83.4) -> 84.233333 | T7: 84.7 | U7: =R7-Q7 -> -0.83333333 | V7: =T7-S7 -> 0.46666667 | W7: =AVERAGE(U7,V7) -> -0.18333333 | X7: =IFERROR(IF(W7<10,"NEGATIVE",IF(W7>20,"POSITIVE","SUSPECT")),"") -> NEGATIVE | Y7: NEGATIVE | Z7: NEGATIVE | AA7: =IF(X7="POSITIVE","POSITIVE",IF(Y7="POSITIVE","POSITIVE",IF(Z7="POSITIVE","POSITIVE","NEGATIVE"))) -> NEGATIVE | AB7: Stephens Creek
A8: Bison_02/21/2022_007 | B8: 44613 | C8: 81HL6107 | D8: 81BEV8312 | E8: NA | F8: M | G8: Y | H8: 7 | I8: 2 | J8: NA | K8: NA | L8: 730 | M8: NA | N8: NA | P8: Quarantine | Q8: =AVERAGE(83.7,85.6,83.4) -> 84.233333 | R8: 79.9 | S8: =AVERAGE(83.7,85.6,83.4) -> 84.233333 | T8: 76.9 | U8: =R8-Q8 -> -4.3333333 | V8: =T8-S8 -> -7.3333333 | W8: =AVERAGE(U8,V8) -> -5.8333333 | X8: =IFERROR(IF(W8<10,"NEGATIVE",IF(W8>20,"POSITIVE","SUSPECT")),"") -> NEGATIVE | Y8: NEGATIVE | Z8: NEGATIVE | AA8: =IF(X8="POSITIVE","POSITIVE",IF(Y8="POSITIVE","POSITIVE",IF(Z8="POSITIVE","POSITIVE","NEGATIVE"))) -> NEGATIVE | AB8: Stephens Creek
A9: Bison_02/21/2022_008 | B9: 44613 | C9: 81HL6108 | D9: 81BEV8313 | E9: NA | F9: F | G9: C | H9: 8 | I9: 1 | J9: NA | K9: NA | L9: 390 | M9: NA | N9: NA | P9: Released | Q9: =AVERAGE(83.7,85.6,83.4) -> 84.233333 | R9: 124.5 | S9: =AVERAGE(83.7,85.6,83.4) -> 84.233333 | T9: 123.1 | U9: =R9-Q9 -> 40.266667 | V9: =T9-S9 -> 38.866667 | W9: =AVERAGE(U9,V9) -> 39.566667 | X9: =IFERROR(IF(W9<10,"NEGATIVE",IF(W9>20,"POSITIVE","SUSPECT")),"") -> POSITIVE | Y9: NEGATIVE | Z9: POSITIVE | AA9: =IF(X9="POSITIVE","POSITIVE",IF(Y9="POSITIVE","POSITIVE",IF(Z9="POSITIVE","POSITIVE","NEGATIVE"))) -> POSITIVE | AB9: NA
A10: Bison_02/21/2022_009 | B10: 44613 | C10: 81HL6109 | D10: 81BEV8314 | E10: NA | F10: F | G10: C | H10: 9 | I10: 1 | J10: NA | K10: NA | L10: 390 | M10: NA | N10: NA | P10: Quarantine | Q10: =AVERAGE(83.7,85.6,83.4) -> 84.233333 | R10: 81.9 | S10: =AVERAGE(83.7,85.6,83.4) -> 84.233333 | T10: 82.4 | U10: =R10-Q10 -> -2.3333333 | V10: =T10-S10 -> -1.8333333 | W10: =AVERAGE(U10,V10) -> -2.0833333 | X10: =IFERROR(IF(W10<10,"NEGATIVE",IF(W10>20,"POSITIVE","SUSPECT")),"") -> NEGATIVE | Y10: NEGATIVE | Z10: NEGATIVE | AA10: =IF(X10="POSITIVE","POSITIVE",IF(Y10="POSITIVE","POSITIVE",IF(Z10="POSITIVE","POSITIVE","NEGATIVE"))) -> NEGATIVE | AB10: Stephens Creek
A11: Bison_02/21/2022_010 | B11: 44613 | C11: 81HL6181 | D11: NA | E11: NA | F11: F | G11: A | H11: NA | I11: 4 | J11: NA | K11: NA | L11: NA | M11: NA | N11: NA | P11: Slaughter | Q11: NA | R11: NA | S11: NA | T11: NA | U11: NA | V11: NA | W11: NA | X11: NA | Y11: NA | Z11: NA | AA11: NA | AB11: Tizers
A12: Bison_02/21/2022_011 | B12: 44613 | C12: 81HL6180 | D12: NA | E12: NA | F12: M | G12: C | H12: NA | I12: 3 | J12: NA | K12: NA | L12: NA | M12: NA | N12: NA | P12: Released | Q12: NA | R12: NA | S12: NA | T12: NA | U12: NA | V12: NA | W12: NA | X12: NA | Y12: NA | Z12: NA | AA12: NA | AB12: NA
A13: Bison_02/21/2022_012 | B13: 44613 | C13: 81HL6179 | D13: NA | E13: NA | F13: F | G13: A | H13: NA | I13: 5 | J13: NA | K13: NA | L13: NA | M13: NA | N13: NA | P13: Slaughter | Q13: NA | R13: NA | S13: NA | T13: NA | U13: NA | V13: NA | W13: NA | X13: NA | Y13: NA | Z13: NA | AA13: NA | AB13: Tizers
A14: Bison_02/21/2022_013 | B14: 44613 | C14: 81HL6178 | D14: NA | E14: NA | F14: F | G14: A | H14: NA | I14: 5 | J14: NA | K14: NA | L14: NA | M14: NA | N14: NA | P14: Slaughter | Q14: NA | R14: NA | S14: NA | T14: NA | U14: NA | V14: NA | W14: NA | X14: NA | Y14: NA | Z14: NA | AA14: NA | AB14: Tizers
A15: Bison_02/21/2022_014 | B15: 44613 | C15: 81HL6177 | D15: NA | E15: NA | F15: M | G15: C | H15: NA | I15: 3 | J15: NA | K15: NA | L15: NA | M15: NA | N15: NA | P15: Released | Q15: NA | R15: NA | S15: NA | T15: NA | U15: NA | V15: NA | W15: NA | X15: NA | Y15: NA | Z15: NA | AA15: NA | AB15: NA
A16: Bison_02/21/2022_015 | B16: 44613 | C16: 81HL6197 | D16: NA | E16: NA | F16: F | G16: A | H16: NA | I16: 5 | J16: NA | K16: NA | L16: NA | M16: NA | N16: NA | P16: Slaughter | Q16: NA | R16: NA | S16: NA | T16: NA | U16: NA | V16: NA | W16: NA | X16: NA | Y16: NA | Z16: NA | AA16: NA | AB16: Tizers
A17: Bison_02/21/2022_016 | B17: 44613 | C17: 81HL6176 | D17: NA | E17: NA | F17: M | G17: A | H17: NA | I17: 5 | J17: NA | K17: NA | L17: NA | M17: NA | N17: NA | P17: Slaughter | Q17: NA | R17: NA | S17: NA | T17: NA | U17: NA | V17: NA | W17: NA | X17: NA | Y17: NA | Z17: NA | AA17: NA | AB17: Tizers
A18: Bison_02/21/2022_017 | B18: 44613 | C18: 81HL6175 | D18: NA | E18: NA | F18: M | G18: A | H18: NA | I18: 5 | J18: NA | K18: NA | L18: NA | M18: NA | N18: NA | P18: Slaughter | Q18: NA | R18: NA | S18: NA | T18: NA | U18: NA | V18: NA | W18: NA | X18: NA | Y18: NA | Z18: NA | AA18: NA | AB18: Tizers
A19: Bison_02/21/2022_018 | B19: 44613 | C19: 81HL6200 | D19: NA | E19: NA | F19: M | G19: C | H19: NA | I19: 3 | J19: NA | K19: NA | L19: NA | M19: NA | N19: NA | P19: Released | Q19: NA | R19: NA | S19: NA | T19: NA | U19: NA | V19: NA | W19: NA | X19: NA | Y19: NA | Z19: NA | AA19: NA | AB19: NA
A20: Bison_02/21/2022_019 | B20: 44613 | C20: 81HL6151 | D20: NA | E20: NA | F20: F | G20: A | H20: NA | I20: 4 | J20: NA | K20: NA | L20: NA | M20: NA | N20: NA | P20: Slaughter | Q20: NA | R20: NA | S20: NA | T20: NA | U20: NA | V20: NA | W20: NA | X20: NA | Y20: NA | Z20: NA | AA20: NA | AB20: Tizers
A21: Bison_02/21/2022_020 | B21: 44613 | C21: 81HL6199 | D21: NA | E21: NA | F21: F | G21: A | H21: NA | I21: 4 | J21: NA | K21: NA | L21: NA | M21: NA | N21: NA | P21: Slaughter | Q21: NA | R21: NA | S21: NA | T21: NA | U21: NA | V21: NA | W21: NA | X21: NA | Y21: NA | Z21: NA | AA21: NA | AB21: Tizers
A22: Bison_02/21/2022_021 | B22: 44613 | C22: 81HL6152 | D22: NA | E22: NA | F22: F | G22: A | H22: NA | I22: 4 | J22: NA | K22: NA | L22: NA | M22: NA | N22: NA | P22: Slaughter | Q22: NA | R22: NA | S22: NA | T22: NA | U22: NA | V22: NA | W22: NA | X22: NA | Y22: NA | Z22: NA | AA22: NA | AB22: Tizers
... A38: Bison_02/21/2022_037 | B38: 44613 | C38: 81HL6174 | D38: NA | E38: NA | F38: F | G38: A | H38: NA | I38: 5 | J38: NA | K38: NA | L38: NA | M38: NA | N38: NA | P38: Slaughter | Q38: NA | R38: NA | S38: NA | T38: NA | U38: NA | V38: NA | W38: NA | X38: NA | Y38: NA | Z38: NA | AA38: NA | AB38: Tizers
A39: Bison_02/21/2022_038 | B39: 44613 | C39: NA | D39: NA | E39: NA | F39: M | G39: Y | H39: NA | I39: NA | J39: NA | K39: NA | L39: NA | M39: NA | N39: NA | O39: Escaped squeeze | P39: Released | Q39: NA | R39: NA | S39: NA | T39: NA | U39: NA | V39: NA | W39: NA | X39: NA | Y39: NA | Z39: NA | AA39: NA | AB39: NA

Sheet Shipping Class
A1: Date | B1: AM | C1: YM | D1: AF | E1: YF | F1: C | G1: Total
A2: {=IF(_xlfn.UNIQUE(Trapside!B5:B1005,FALSE,FALSE)>1/1/2022,_xlfn.UNIQUE(Trapside!B5:B1005,FALSE,FALSE),"")} -> 44613 | B2: =IF(A2<>"",COUNTIFS(Trapside!F:F,"M",Trapside!G:G,"A",Trapside!P:P,"SLAUGHTER"),"") -> 5 | C2: =IF(A2<>"",COUNTIFS(Trapside!F:F,"M",Trapside!G:G,"Y",Trapside!P:P,"SLAUGHTER"),"") -> 2 | D2: =IF(A2<>"",COUNTIFS(Trapside!F:F,"F",Trapside!G:G,"A",Trapside!P:P,"SLAUGHTER"),"") -> 20 | E2: =IF(A2<>"",COUNTIFS(Trapside!F:F,"F",Trapside!G:G,"Y",Trapside!P:P,"SLAUGHTER"),"") -> 0 | F2: =IF(A2<>"",COUNTIFS(Trapside!G:G,"C",Trapside!P:P,"SLAUGHTER"),"") -> 0 | G2: =IF(A2<>"",SUM(B2:F2),"") -> 27
B3: =IF(A3<>"",COUNTIFS(Trapside!F:F,"M",Trapside!G:G,"A",Trapside!P:P,"SLAUGHTER"),"") | C3: =IF(A3<>"",COUNTIFS(Trapside!F:F,"M",Trapside!G:G,"Y",Trapside!P:P,"SLAUGHTER"),"") | D3: =IF(A3<>"",COUNTIFS(Trapside!F:F,"F",Trapside!G:G,"A",Trapside!P:P,"SLAUGHTER"),"") | E3: =IF(A3<>"",COUNTIFS(Trapside!F:F,"F",Trapside!G:G,"Y",Trapside!P:P,"SLAUGHTER"),"") | F3: =IF(A3<>"",COUNTIFS(Trapside!G:G,"C",Trapside!P:P,"SLAUGHTER"),"") | G3: =IF(A3<>"",SUM(B3:F3),"")
B4: =IF(A4<>"",COUNTIFS(Trapside!F:F,"M",Trapside!G:G,"A",Trapside!P:P,"SLAUGHTER"),"") | C4: =IF(A4<>"",COUNTIFS(Trapside!F:F,"M",Trapside!G:G,"Y",Trapside!P:P,"SLAUGHTER"),"") | D4: =IF(A4<>"",COUNTIFS(Trapside!F:F,"F",Trapside!G:G,"A",Trapside!P:P,"SLAUGHTER"),"") | E4: =IF(A4<>"",COUNTIFS(Trapside!F:F,"F",Trapside!G:G,"Y",Trapside!P:P,"SLAUGHTER"),"") | F4: =IF(A4<>"",COUNTIFS(Trapside!G:G,"C",Trapside!P:P,"SLAUGHTER"),"") | G4: =IF(A4<>"",SUM(B4:F4),"")
B5: =IF(A5<>"",COUNTIFS(Trapside!F:F,"M",Trapside!G:G,"A",Trapside!P:P,"SLAUGHTER"),"") | C5: =IF(A5<>"",COUNTIFS(Trapside!F:F,"M",Trapside!G:G,"Y",Trapside!P:P,"SLAUGHTER"),"") | D5: =IF(A5<>"",COUNTIFS(Trapside!F:F,"F",Trapside!G:G,"A",Trapside!P:P,"SLAUGHTER"),"") | E5: =IF(A5<>"",COUNTIFS(Trapside!F:F,"F",Trapside!G:G,"Y",Trapside!P:P,"SLAUGHTER"),"") | F5: =IF(A5<>"",COUNTIFS(Trapside!G:G,"C",Trapside!P:P,"SLAUGHTER"),"") | G5: =IF(A5<>"",SUM(B5:F5),"")
B6: =IF(A6<>"",COUNTIFS(Trapside!F:F,"M",Trapside!G:G,"A",Trapside!P:P,"SLAUGHTER"),"") | C6: =IF(A6<>"",COUNTIFS(Trapside!F:F,"M",Trapside!G:G,"Y",Trapside!P:P,"SLAUGHTER"),"") | D6: =IF(A6<>"",COUNTIFS(Trapside!F:F,"F",Trapside!G:G,"A",Trapside!P:P,"SLAUGHTER"),"") | E6: =IF(A6<>"",COUNTIFS(Trapside!F:F,"F",Trapside!G:G,"Y",Trapside!P:P,"SLAUGHTER"),"") | F6: =IF(A6<>"",COUNTIFS(Trapside!G:G,"C",Trapside!P:P,"SLAUGHTER"),"") | G6: =IF(A6<>"",SUM(B6:F6),"")
B7: =IF(A7<>"",COUNTIFS(Trapside!F:F,"M",Trapside!G:G,"A",Trapside!P:P,"SLAUGHTER"),"") | C7: =IF(A7<>"",COUNTIFS(Trapside!F:F,"M",Trapside!G:G,"Y",Trapside!P:P,"SLAUGHTER"),"") | D7: =IF(A7<>"",COUNTIFS(Trapside!F:F,"F",Trapside!G:G,"A",Trapside!P:P,"SLAUGHTER"),"") | E7: =IF(A7<>"",COUNTIFS(Trapside!F:F,"F",Trapside!G:G,"Y",Trapside!P:P,"SLAUGHTER"),"") | F7: =IF(A7<>"",COUNTIFS(Trapside!G:G,"C",Trapside!P:P,"SLAUGHTER"),"") | G7: =IF(A7<>"",SUM(B7:F7),"")
B8: =IF(A8<>"",COUNTIFS(Trapside!F:F,"M",Trapside!G:G,"A",Trapside!P:P,"SLAUGHTER"),"") | C8: =IF(A8<>"",COUNTIFS(Trapside!F:F,"M",Trapside!G:G,"Y",Trapside!P:P,"SLAUGHTER"),"") | D8: =IF(A8<>"",COUNTIFS(Trapside!F:F,"F",Trapside!G:G,"A",Trapside!P:P,"SLAUGHTER"),"") | E8: =IF(A8<>"",COUNTIFS(Trapside!F:F,"F",Trapside!G:G,"Y",Trapside!P:P,"SLAUGHTER"),"") | F8: =IF(A8<>"",COUNTIFS(Trapside!G:G,"C",Trapside!P:P,"SLAUGHTER"),"") | G8: =IF(A8<>"",SUM(B8:F8),"")
B9: =IF(A9<>"",COUNTIFS(Trapside!F:F,"M",Trapside!G:G,"A",Trapside!P:P,"SLAUGHTER"),"") | C9: =IF(A9<>"",COUNTIFS(Trapside!F:F,"M",Trapside!G:G,"Y",Trapside!P:P,"SLAUGHTER"),"") | D9: =IF(A9<>"",COUNTIFS(Trapside!F:F,"F",Trapside!G:G,"A",Trapside!P:P,"SLAUGHTER"),"") | E9: =IF(A9<>"",COUNTIFS(Trapside!F:F,"F",Trapside!G:G,"Y",Trapside!P:P,"SLAUGHTER"),"") | F9: =IF(A9<>"",COUNTIFS(Trapside!G:G,"C",Trapside!P:P,"SLAUGHTER"),"") | G9: =IF(A9<>"",SUM(B9:F9),"")
B10: =IF(A10<>"",COUNTIFS(Trapside!F:F,"M",Trapside!G:G,"A",Trapside!P:P,"SLAUGHTER"),"") | C10: =IF(A10<>"",COUNTIFS(Trapside!F:F,"M",Trapside!G:G,"Y",Trapside!P:P,"SLAUGHTER"),"") | D10: =IF(A10<>"",COUNTIFS(Trapside!F:F,"F",Trapside!G:G,"A",Trapside!P:P,"SLAUGHTER"),"") | E10: =IF(A10<>"",COUNTIFS(Trapside!F:F,"F",Trapside!G:G,"Y",Trapside!P:P,"SLAUGHTER"),"") | F10: =IF(A10<>"",COUNTIFS(Trapside!G:G,"C",Trapside!P:P,"SLAUGHTER"),"") | G10: =IF(A10<>"",SUM(B10:F10),"")
B11: =IF(A11<>"",COUNTIFS(Trapside!F:F,"M",Trapside!G:G,"A",Trapside!P:P,"SLAUGHTER"),"") | C11: =IF(A11<>"",COUNTIFS(Trapside!F:F,"M",Trapside!G:G,"Y",Trapside!P:P,"SLAUGHTER"),"") | D11: =IF(A11<>"",COUNTIFS(Trapside!F:F,"F",Trapside!G:G,"A",Trapside!P:P,"SLAUGHTER"),"") | E11: =IF(A11<>"",COUNTIFS(Trapside!F:F,"F",Trapside!G:G,"Y",Trapside!P:P,"SLAUGHTER"),"") | F11: =IF(A11<>"",COUNTIFS(Trapside!G:G,"C",Trapside!P:P,"SLAUGHTER"),"") | G11: =IF(A11<>"",SUM(B11:F11),"")
B12: =IF(A12<>"",COUNTIFS(Trapside!F:F,"M",Trapside!G:G,"A",Trapside!P:P,"SLAUGHTER"),"") | C12: =IF(A12<>"",COUNTIFS(Trapside!F:F,"M",Trapside!G:G,"Y",Trapside!P:P,"SLAUGHTER"),"") | D12: =IF(A12<>"",COUNTIFS(Trapside!F:F,"F",Trapside!G:G,"A",Trapside!P:P,"SLAUGHTER"),"") | E12: =IF(A12<>"",COUNTIFS(Trapside!F:F,"F",Trapside!G:G,"Y",Trapside!P:P,"SLAUGHTER"),"") | F12: =IF(A12<>"",COUNTIFS(Trapside!G:G,"C",Trapside!P:P,"SLAUGHTER"),"") | G12: =IF(A12<>"",SUM(B12:F12),"")
B13: =IF(A13<>"",COUNTIFS(Trapside!F:F,"M",Trapside!G:G,"A",Trapside!P:P,"SLAUGHTER"),"") | C13: =IF(A13<>"",COUNTIFS(Trapside!F:F,"M",Trapside!G:G,"Y",Trapside!P:P,"SLAUGHTER"),"") | D13: =IF(A13<>"",COUNTIFS(Trapside!F:F,"F",Trapside!G:G,"A",Trapside!P:P,"SLAUGHTER"),"") | E13: =IF(A13<>"",COUNTIFS(Trapside!F:F,"F",Trapside!G:G,"Y",Trapside!P:P,"SLAUGHTER"),"") | F13: =IF(A13<>"",COUNTIFS(Trapside!G:G,"C",Trapside!P:P,"SLAUGHTER"),"") | G13: =IF(A13<>"",SUM(B13:F13),"")
B14: =IF(A14<>"",COUNTIFS(Trapside!F:F,"M",Trapside!G:G,"A",Trapside!P:P,"SLAUGHTER"),"") | C14: =IF(A14<>"",COUNTIFS(Trapside!F:F,"M",Trapside!G:G,"Y",Trapside!P:P,"SLAUGHTER"),"") | D14: =IF(A14<>"",COUNTIFS(Trapside!F:F,"F",Trapside!G:G,"A",Trapside!P:P,"SLAUGHTER"),"") | E14: =IF(A14<>"",COUNTIFS(Trapside!F:F,"F",Trapside!G:G,"Y",Trapside!P:P,"SLAUGHTER"),"") | F14: =IF(A14<>"",COUNTIFS(Trapside!G:G,"C",Trapside!P:P,"SLAUGHTER"),"") | G14: =IF(A14<>"",SUM(B14:F14),"")
... B21: =IF(A21<>"",COUNTIFS(Trapside!F:F,"M",Trapside!G:G,"A",Trapside!P:P,"SLAUGHTER"),"") | C21: =IF(A21<>"",COUNTIFS(Trapside!F:F,"M",Trapside!G:G,"Y",Trapside!P:P,"SLAUGHTER"),"") | D21: =IF(A21<>"",COUNTIFS(Trapside!F:F,"F",Trapside!G:G,"A",Trapside!P:P,"SLAUGHTER"),"") | E21: =IF(A21<>"",COUNTIFS(Trapside!F:F,"F",Trapside!G:G,"Y",Trapside!P:P,"SLAUGHTER"),"") | F21: =IF(A21<>"",COUNTIFS(Trapside!G:G,"C",Trapside!P:P,"SLAUGHTER"),"") | G21: =IF(A21<>"",SUM(B21:F21),"")
